Workbook
Name Año: 'INC. POR SEXO 2022'!#REF!+'INC. POR SEXO 2022'!#REF!
Name AÑO: 'INC. POR SEXO 2022'!#REF!
Name AÑO: 'INC. POR SEXO 2022'!#REF!
Name AÑO: 'INC. POR SEXO 2022'!#REF!
Name AYAPEL: OFFSET(Tabla_mapa!$C$1,MATCH('Mapa Razón'!$F$11,Tabla_mapa!$A$2:$A$4,0),0,1,1)
Name AYAPEL: OFFSET(Tabla_mapa!$C$1,MATCH('Mapa incidencia'!$F$11,Tabla_mapa!$A$2:$A$4,0),0,1,1)
Name BUENAVISTA: OFFSET(Tabla_mapa!$D$1,MATCH('Mapa Razón'!$F$12,Tabla_mapa!$A$2:$A$4,0),0,1,1)
Name BUENAVISTA: OFFSET(Tabla_mapa!$D$1,MATCH('Mapa incidencia'!$F$12,Tabla_mapa!$A$2:$A$4,0),0,1,1)
Name CANALETE: OFFSET(Tabla_mapa!$E$1,MATCH('Mapa Razón'!$F$13,Tabla_mapa!$A$2:$A$4,0),0,1,1)
Name CANALETE: OFFSET(Tabla_mapa!$E$1,MATCH('Mapa incidencia'!$F$13,Tabla_mapa!$A$2:$A$4,0),0,1,1)
Name CERETE: OFFSET(Tabla_mapa!$F$1,MATCH('Mapa Razón'!$F$14,Tabla_mapa!$A$2:$A$4,0),0,1,1)
Name CERETE: OFFSET(Tabla_mapa!$F$1,MATCH('Mapa incidencia'!$F$14,Tabla_mapa!$A$2:$A$4,0),0,1,1)
Name CHIMA: OFFSET(Tabla_mapa!$G$1,MATCH('Mapa Razón'!$F$15,Tabla_mapa!$A$2:$A$4,0),0,1,1)
Name CHIMA: OFFSET(Tabla_mapa!$G$1,MATCH('Mapa incidencia'!$F$15,Tabla_mapa!$A$2:$A$4,0),0,1,1)
Name CHINU: OFFSET(Tabla_mapa!$H$1,MATCH('Mapa Razón'!$F$16,Tabla_mapa!$A$2:$A$4,0),0,1,1)
Name CHINU: OFFSET(Tabla_mapa!$H$1,MATCH('Mapa incidencia'!$F$16,Tabla_mapa!$A$2:$A$4,0),0,1,1)
Name CIENAGA_DE_ORO: OFFSET(Tabla_mapa!$I$1,MATCH('Mapa Razón'!$F$17,Tabla_mapa!$A$2:$A$4,0),0,1,1)
Name CIENAGA_DE_ORO: OFFSET(Tabla_mapa!$I$1,MATCH('Mapa incidencia'!$F$17,Tabla_mapa!$A$2:$A$4,0),0,1,1)
Name COTORRA: OFFSET(Tabla_mapa!$J$1,MATCH('Mapa Razón'!$F$18,Tabla_mapa!$A$2:$A$4,0),0,1,1)
Name COTORRA: OFFSET(Tabla_mapa!$J$1,MATCH('Mapa incidencia'!$F$18,Tabla_mapa!$A$2:$A$4,0),0,1,1)
Name LA_APARTADA: OFFSET(Tabla_mapa!$K$1,MATCH('Mapa Razón'!$F$19,Tabla_mapa!$A$2:$A$4,0),0,1,1)
Name LA_APARTADA: OFFSET(Tabla_mapa!$K$1,MATCH('Mapa incidencia'!$F$19,Tabla_mapa!$A$2:$A$4,0),0,1,1)
Name LORICA: OFFSET(Tabla_mapa!$L$1,MATCH('Mapa Razón'!$F$20,Tabla_mapa!$A$2:$A$4,0),0,1,1)
Name LORICA: OFFSET(Tabla_mapa!$L$1,MATCH('Mapa incidencia'!$F$20,Tabla_mapa!$A$2:$A$4,0),0,1,1)
Name LOS_CORDOBAS: OFFSET(Tabla_mapa!$M$1,MATCH('Mapa Razón'!$F$21,Tabla_mapa!$A$2:$A$4,0),0,1,1)
Name LOS_CORDOBAS: OFFSET(Tabla_mapa!$M$1,MATCH('Mapa incidencia'!$F$21,Tabla_mapa!$A$2:$A$4,0),0,1,1)
Name MOMIL: OFFSET(Tabla_mapa!$N$1,MATCH('Mapa Razón'!$F$22,Tabla_mapa!$A$2:$A$4,0),0,1,1)
Name MOMIL: OFFSET(Tabla_mapa!$N$1,MATCH('Mapa incidencia'!$F$22,Tabla_mapa!$A$2:$A$4,0),0,1,1)
Name MONTELIBANO: OFFSET(Tabla_mapa!$O$1,MATCH('Mapa Razón'!$F$23,Tabla_mapa!$A$2:$A$4,0),0,1,1)
Name MONTELIBANO: OFFSET(Tabla_mapa!$O$1,MATCH('Mapa incidencia'!$F$23,Tabla_mapa!$A$2:$A$4,0),0,1,1)
Name MONTERIA: OFFSET(Tabla_mapa!$B$1,MATCH('Mapa Razón'!$F$10,Tabla_mapa!$A$2:$A$4,0),0,1,1)
Name MONTERIA: OFFSET(Tabla_mapa!$B$1,MATCH('Mapa incidencia'!$F$10,Tabla_mapa!$A$2:$A$4,0),0,1,1)
Name MOÑITOS: OFFSET(Tabla_mapa!$P$1,MATCH('Mapa Razón'!$F$24,Tabla_mapa!$A$2:$A$4,0),0,1,1)
Name MOÑITOS: OFFSET(Tabla_mapa!$P$1,MATCH('Mapa incidencia'!$F$24,Tabla_mapa!$A$2:$A$4,0),0,1,1)
Name MPIO_RESI: '[1]BD Nacimientos'!$AI:$AI
Name PLANETA_RICA: OFFSET(Tabla_mapa!$Q$1,MATCH('Mapa Razón'!$F$25,Tabla_mapa!$A$2:$A$4,0),0,1,1)
Name PLANETA_RICA: OFFSET(Tabla_mapa!$Q$1,MATCH('Mapa incidencia'!$F$25,Tabla_mapa!$A$2:$A$4,0),0,1,1)
Name PUEBLO_NUEVO: OFFSET(Tabla_mapa!$R$1,MATCH('Mapa Razón'!$F$26,Tabla_mapa!$A$2:$A$4,0),0,1,1)
Name PUEBLO_NUEVO: OFFSET(Tabla_mapa!$R$1,MATCH('Mapa incidencia'!$F$26,Tabla_mapa!$A$2:$A$4,0),0,1,1)
Name PUERTO_ESCONDIDO: OFFSET(Tabla_mapa!$S$1,MATCH('Mapa Razón'!$F$27,Tabla_mapa!$A$2:$A$4,0),0,1,1)
Name PUERTO_ESCONDIDO: OFFSET(Tabla_mapa!$S$1,MATCH('Mapa incidencia'!$F$27,Tabla_mapa!$A$2:$A$4,0),0,1,1)
Name PUERTO_LIBERTADOR: OFFSET(Tabla_mapa!$T$1,MATCH('Mapa Razón'!$F$28,Tabla_mapa!$A$2:$A$4,0),0,1,1)
Name PUERTO_LIBERTADOR: OFFSET(Tabla_mapa!$T$1,MATCH('Mapa incidencia'!$F$28,Tabla_mapa!$A$2:$A$4,0),0,1,1)
Name PURISIMA: OFFSET(Tabla_mapa!$U$1,MATCH('Mapa Razón'!$F$29,Tabla_mapa!$A$2:$A$4,0),0,1,1)
Name PURISIMA: OFFSET(Tabla_mapa!$U$1,MATCH('Mapa incidencia'!$F$29,Tabla_mapa!$A$2:$A$4,0),0,1,1)
Name SAHAGUN: OFFSET(Tabla_mapa!$V$1,MATCH('Mapa Razón'!$F$30,Tabla_mapa!$A$2:$A$4,0),0,1,1)
Name SAHAGUN: OFFSET(Tabla_mapa!$V$1,MATCH('Mapa incidencia'!$F$30,Tabla_mapa!$A$2:$A$4,0),0,1,1)
Name SAN_ANDRES: OFFSET(Tabla_mapa!$W$1,MATCH('Mapa Razón'!$F$31,Tabla_mapa!$A$2:$A$4,0),0,1,1)
Name SAN_ANDRES: OFFSET(Tabla_mapa!$W$1,MATCH('Mapa incidencia'!$F$31,Tabla_mapa!$A$2:$A$4,0),0,1,1)
Name SAN_ANTERO: OFFSET(Tabla_mapa!$X$1,MATCH('Mapa Razón'!$F$32,Tabla_mapa!$A$2:$A$4,0),0,1,1)
Name SAN_ANTERO: OFFSET(Tabla_mapa!$X$1,MATCH('Mapa incidencia'!$F$32,Tabla_mapa!$A$2:$A$4,0),0,1,1)
Name SAN_BERNARDO: OFFSET(Tabla_mapa!$Y$1,MATCH('Mapa Razón'!$F$33,Tabla_mapa!$A$2:$A$4,0),0,1,1)
Name SAN_BERNARDO: OFFSET(Tabla_mapa!$Y$1,MATCH('Mapa incidencia'!$F$33,Tabla_mapa!$A$2:$A$4,0),0,1,1)
Name SAN_CARLOS: OFFSET(Tabla_mapa!$Z$1,MATCH('Mapa Razón'!$F$34,Tabla_mapa!$A$2:$A$4,0),0,1,1)
Name SAN_CARLOS: OFFSET(Tabla_mapa!$Z$1,MATCH('Mapa incidencia'!$F$34,Tabla_mapa!$A$2:$A$4,0),0,1,1)
Name SAN_JOSE_DE_URE: OFFSET(Tabla_mapa!$AA$1,MATCH('Mapa Razón'!$F$35,Tabla_mapa!$A$2:$A$4,0),0,1,1)
Name SAN_JOSE_DE_URE: OFFSET(Tabla_mapa!$AA$1,MATCH('Mapa incidencia'!$F$35,Tabla_mapa!$A$2:$A$4,0),0,1,1)
Name SAN_PELAYO: OFFSET(Tabla_mapa!$AB$1,MATCH('Mapa Razón'!$F$36,Tabla_mapa!$A$2:$A$4,0),0,1,1)
Name SAN_PELAYO: OFFSET(Tabla_mapa!$AB$1,MATCH('Mapa incidencia'!$F$36,Tabla_mapa!$A$2:$A$4,0),0,1,1)
Name TIERRALTA: OFFSET(Tabla_mapa!$AC$1,MATCH('Mapa Razón'!$F$37,Tabla_mapa!$A$2:$A$4,0),0,1,1)

Sheet INCIDENCIA ACUMULADA
A1: MUNICIPIO | B1: CASOS | C1: POBLACIÓN TOTAL | D1: INCIDENCIA ACUMULADA TOTAL | E1: MUNICIPIO | F1: POB. TOTAL | H1: AÑO | K1: 2022 | L1: 100
A2: Ayapel | B2: 10 | C2: =(IF(A2="MONTERIA",$F$2,IF(A2="AYAPEL",$F$3,IF(A2="BUENAVISTA",$F$4,IF(A2="CANALETE",$F$5,IF(A2="CERETE",$F$6,IF(A2="CHIMA",$F$7,IF(A2="CHINU",$F$8,IF(A2="CIENAGA DE ORO",$F$9,IF(A2="COTORRA",$F$10,IF(A2="LA APARTADA",$F$11,IF(A2="LORICA",$F$12,IF(A2="LOS CORDOBAS",$F$13,IF(A2="MOMIL",$F$14,IF(A2="MONTELIBANO",$F$15,IF(A2="MOÑITOS",$F$16,IF(A2="PLANETA RICA",$F$17,IF(A2="PUEBLO NUEVO",$F$18,IF(A2="PUERTO ESCONDIDO",$F$19,IF(A2="PUERTO LIBERTADOR",$F$20,IF(A2="PURISIMA",$F$21,IF(A2="SAHAGUN",$F$22,IF(A2="SAN ANDRES SOTAVENTO",$F$23,IF(A2="SAN ANTERO",$F$24,IF(A2="SAN BERNARDO DEL VIENTO",$F$25,IF(A2="SAN CARLOS",$F$26,IF(A2="SAN JOSE DE URE",$F$27,IF(A2="SAN PELAYO",$F$28,IF(A2="TIERRALTA",$F$29,IF(A2="TUCHIN",$F$30,IF(A2="VALENCIA",$F$31))))))))))))))))))))))))))))))) -> 47954 | D2: =IFERROR(B2/C2*$F$34,"0") -> 20.853318 | E2: MONTERIA | F2: =IF($H$2=2022,POBLACIÓN!F6,POBLACIÓN!G6) -> 512994 | H2: 2022 | K2: 2023 | L2: 1000
A3: Buenavista | B3: 20 | C3: =(IF(A3="MONTERIA",$F$2,IF(A3="AYAPEL",$F$3,IF(A3="BUENAVISTA",$F$4,IF(A3="CANALETE",$F$5,IF(A3="CERETE",$F$6,IF(A3="CHIMA",$F$7,IF(A3="CHINU",$F$8,IF(A3="CIENAGA DE ORO",$F$9,IF(A3="COTORRA",$F$10,IF(A3="LA APARTADA",$F$11,IF(A3="LORICA",$F$12,IF(A3="LOS CORDOBAS",$F$13,IF(A3="MOMIL",$F$14,IF(A3="MONTELIBANO",$F$15,IF(A3="MOÑITOS",$F$16,IF(A3="PLANETA RICA",$F$17,IF(A3="PUEBLO NUEVO",$F$18,IF(A3="PUERTO ESCONDIDO",$F$19,IF(A3="PUERTO LIBERTADOR",$F$20,IF(A3="PURISIMA",$F$21,IF(A3="SAHAGUN",$F$22,IF(A3="SAN ANDRES SOTAVENTO",$F$23,IF(A3="SAN ANTERO",$F$24,IF(A3="SAN BERNARDO DEL VIENTO",$F$25,IF(A3="SAN CARLOS",$F$26,IF(A3="SAN JOSE DE URE",$F$27,IF(A3="SAN PELAYO",$F$28,IF(A3="TIERRALTA",$F$29,IF(A3="TUCHIN",$F$30,IF(A3="VALENCIA",$F$31))))))))))))))))))))))))))))))) -> 21772 | D3: =IFERROR(B3/C3*$F$34,"0") -> 91.861106 | E3: AYAPEL | F3: =IF($H$2=2022,POBLACIÓN!F7,POBLACIÓN!G7) -> 47954 | L3: 10000
A4: Canalete | B4: 40 | C4: =(IF(A4="MONTERIA",$F$2,IF(A4="AYAPEL",$F$3,IF(A4="BUENAVISTA",$F$4,IF(A4="CANALETE",$F$5,IF(A4="CERETE",$F$6,IF(A4="CHIMA",$F$7,IF(A4="CHINU",$F$8,IF(A4="CIENAGA DE ORO",$F$9,IF(A4="COTORRA",$F$10,IF(A4="LA APARTADA",$F$11,IF(A4="LORICA",$F$12,IF(A4="LOS CORDOBAS",$F$13,IF(A4="MOMIL",$F$14,IF(A4="MONTELIBANO",$F$15,IF(A4="MOÑITOS",$F$16,IF(A4="PLANETA RICA",$F$17,IF(A4="PUEBLO NUEVO",$F$18,IF(A4="PUERTO ESCONDIDO",$F$19,IF(A4="PUERTO LIBERTADOR",$F$20,IF(A4="PURISIMA",$F$21,IF(A4="SAHAGUN",$F$22,IF(A4="SAN ANDRES SOTAVENTO",$F$23,IF(A4="SAN ANTERO",$F$24,IF(A4="SAN BERNARDO DEL VIENTO",$F$25,IF(A4="SAN CARLOS",$F$26,IF(A4="SAN JOSE DE URE",$F$27,IF(A4="SAN PELAYO",$F$28,IF(A4="TIERRALTA",$F$29,IF(A4="TUCHIN",$F$30,IF(A4="VALENCIA",$F$31))))))))))))))))))))))))))))))) -> 15668 | D4: =IFERROR(B4/C4*$F$34,"0") -> 255.29742 | E4: BUENAVISTA | F4: =IF($H$2=2022,POBLACIÓN!F8,POBLACIÓN!G8) -> 21772 | L4: 100000
A5: Cerete | B5: 47 | C5: =(IF(A5="MONTERIA",$F$2,IF(A5="AYAPEL",$F$3,IF(A5="BUENAVISTA",$F$4,IF(A5="CANALETE",$F$5,IF(A5="CERETE",$F$6,IF(A5="CHIMA",$F$7,IF(A5="CHINU",$F$8,IF(A5="CIENAGA DE ORO",$F$9,IF(A5="COTORRA",$F$10,IF(A5="LA APARTADA",$F$11,IF(A5="LORICA",$F$12,IF(A5="LOS CORDOBAS",$F$13,IF(A5="MOMIL",$F$14,IF(A5="MONTELIBANO",$F$15,IF(A5="MOÑITOS",$F$16,IF(A5="PLANETA RICA",$F$17,IF(A5="PUEBLO NUEVO",$F$18,IF(A5="PUERTO ESCONDIDO",$F$19,IF(A5="PUERTO LIBERTADOR",$F$20,IF(A5="PURISIMA",$F$21,IF(A5="SAHAGUN",$F$22,IF(A5="SAN ANDRES SOTAVENTO",$F$23,IF(A5="SAN ANTERO",$F$24,IF(A5="SAN BERNARDO DEL VIENTO",$F$25,IF(A5="SAN CARLOS",$F$26,IF(A5="SAN JOSE DE URE",$F$27,IF(A5="SAN PELAYO",$F$28,IF(A5="TIERRALTA",$F$29,IF(A5="TUCHIN",$F$30,IF(A5="VALENCIA",$F$31))))))))))))))))))))))))))))))) -> 110032 | D5: =IFERROR(B5/C5*$F$34,"0") -> 42.714847 | E5: CANALETE | F5: =IF($H$2=2022,POBLACIÓN!F9,POBLACIÓN!G9) -> 15668
A6: Chima | B6: 100 | C6: =(IF(A6="MONTERIA",$F$2,IF(A6="AYAPEL",$F$3,IF(A6="BUENAVISTA",$F$4,IF(A6="CANALETE",$F$5,IF(A6="CERETE",$F$6,IF(A6="CHIMA",$F$7,IF(A6="CHINU",$F$8,IF(A6="CIENAGA DE ORO",$F$9,IF(A6="COTORRA",$F$10,IF(A6="LA APARTADA",$F$11,IF(A6="LORICA",$F$12,IF(A6="LOS CORDOBAS",$F$13,IF(A6="MOMIL",$F$14,IF(A6="MONTELIBANO",$F$15,IF(A6="MOÑITOS",$F$16,IF(A6="PLANETA RICA",$F$17,IF(A6="PUEBLO NUEVO",$F$18,IF(A6="PUERTO ESCONDIDO",$F$19,IF(A6="PUERTO LIBERTADOR",$F$20,IF(A6="PURISIMA",$F$21,IF(A6="SAHAGUN",$F$22,IF(A6="SAN ANDRES SOTAVENTO",$F$23,IF(A6="SAN ANTERO",$F$24,IF(A6="SAN BERNARDO DEL VIENTO",$F$25,IF(A6="SAN CARLOS",$F$26,IF(A6="SAN JOSE DE URE",$F$27,IF(A6="SAN PELAYO",$F$28,IF(A6="TIERRALTA",$F$29,IF(A6="TUCHIN",$F$30,IF(A6="VALENCIA",$F$31))))))))))))))))))))))))))))))) -> 18173 | D6: =IFERROR(B6/C6*$F$34,"0") -> 550.26688 | E6: CERETE | F6: =IF($H$2=2022,POBLACIÓN!F10,POBLACIÓN!G10) -> 110032
A7: Chinu | B7: 19 | C7: =(IF(A7="MONTERIA",$F$2,IF(A7="AYAPEL",$F$3,IF(A7="BUENAVISTA",$F$4,IF(A7="CANALETE",$F$5,IF(A7="CERETE",$F$6,IF(A7="CHIMA",$F$7,IF(A7="CHINU",$F$8,IF(A7="CIENAGA DE ORO",$F$9,IF(A7="COTORRA",$F$10,IF(A7="LA APARTADA",$F$11,IF(A7="LORICA",$F$12,IF(A7="LOS CORDOBAS",$F$13,IF(A7="MOMIL",$F$14,IF(A7="MONTELIBANO",$F$15,IF(A7="MOÑITOS",$F$16,IF(A7="PLANETA RICA",$F$17,IF(A7="PUEBLO NUEVO",$F$18,IF(A7="PUERTO ESCONDIDO",$F$19,IF(A7="PUERTO LIBERTADOR",$F$20,IF(A7="PURISIMA",$F$21,IF(A7="SAHAGUN",$F$22,IF(A7="SAN ANDRES SOTAVENTO",$F$23,IF(A7="SAN ANTERO",$F$24,IF(A7="SAN BERNARDO DEL VIENTO",$F$25,IF(A7="SAN CARLOS",$F$26,IF(A7="SAN JOSE DE URE",$F$27,IF(A7="SAN PELAYO",$F$28,IF(A7="TIERRALTA",$F$29,IF(A7="TUCHIN",$F$30,IF(A7="VALENCIA",$F$31))))))))))))))))))))))))))))))) -> 49422 | D7: =IFERROR(B7/C7*$F$34,"0") -> 38.444417 | E7: CHIMA | F7: =IF($H$2=2022,POBLACIÓN!F11,POBLACIÓN!G11) -> 18173
A8: Cienaga de Oro | B8: 21 | C8: =(IF(A8="MONTERIA",$F$2,IF(A8="AYAPEL",$F$3,IF(A8="BUENAVISTA",$F$4,IF(A8="CANALETE",$F$5,IF(A8="CERETE",$F$6,IF(A8="CHIMA",$F$7,IF(A8="CHINU",$F$8,IF(A8="CIENAGA DE ORO",$F$9,IF(A8="COTORRA",$F$10,IF(A8="LA APARTADA",$F$11,IF(A8="LORICA",$F$12,IF(A8="LOS CORDOBAS",$F$13,IF(A8="MOMIL",$F$14,IF(A8="MONTELIBANO",$F$15,IF(A8="MOÑITOS",$F$16,IF(A8="PLANETA RICA",$F$17,IF(A8="PUEBLO NUEVO",$F$18,IF(A8="PUERTO ESCONDIDO",$F$19,IF(A8="PUERTO LIBERTADOR",$F$20,IF(A8="PURISIMA",$F$21,IF(A8="SAHAGUN",$F$22,IF(A8="SAN ANDRES SOTAVENTO",$F$23,IF(A8="SAN ANTERO",$F$24,IF(A8="SAN BERNARDO DEL VIENTO",$F$25,IF(A8="SAN CARLOS",$F$26,IF(A8="SAN JOSE DE URE",$F$27,IF(A8="SAN PELAYO",$F$28,IF(A8="TIERRALTA",$F$29,IF(A8="TUCHIN",$F$30,IF(A8="VALENCIA",$F$31))))))))))))))))))))))))))))))) -> 61426 | D8: =IFERROR(B8/C8*$F$34,"0") -> 34.187478 | E8: CHINU | F8: =IF($H$2=2022,POBLACIÓN!F12,POBLACIÓN!G12) -> 49422
A9: Cotorra | B9: 15 | C9: =(IF(A9="MONTERIA",$F$2,IF(A9="AYAPEL",$F$3,IF(A9="BUENAVISTA",$F$4,IF(A9="CANALETE",$F$5,IF(A9="CERETE",$F$6,IF(A9="CHIMA",$F$7,IF(A9="CHINU",$F$8,IF(A9="CIENAGA DE ORO",$F$9,IF(A9="COTORRA",$F$10,IF(A9="LA APARTADA",$F$11,IF(A9="LORICA",$F$12,IF(A9="LOS CORDOBAS",$F$13,IF(A9="MOMIL",$F$14,IF(A9="MONTELIBANO",$F$15,IF(A9="MOÑITOS",$F$16,IF(A9="PLANETA RICA",$F$17,IF(A9="PUEBLO NUEVO",$F$18,IF(A9="PUERTO ESCONDIDO",$F$19,IF(A9="PUERTO LIBERTADOR",$F$20,IF(A9="PURISIMA",$F$21,IF(A9="SAHAGUN",$F$22,IF(A9="SAN ANDRES SOTAVENTO",$F$23,IF(A9="SAN ANTERO",$F$24,IF(A9="SAN BERNARDO DEL VIENTO",$F$25,IF(A9="SAN CARLOS",$F$26,IF(A9="SAN JOSE DE URE",$F$27,IF(A9="SAN PELAYO",$F$28,IF(A9="TIERRALTA",$F$29,IF(A9="TUCHIN",$F$30,IF(A9="VALENCIA",$F$31))))))))))))))))))))))))))))))) -> 19845 | D9: =IFERROR(B9/C9*$F$34,"0") -> 75.58579 | E9: CIENAGA DE ORO | F9: =IF($H$2=2022,POBLACIÓN!F13,POBLACIÓN!G13) -> 61426
A10: La Apartada | B10: 6 | C10: =(IF(A10="MONTERIA",$F$2,IF(A10="AYAPEL",$F$3,IF(A10="BUENAVISTA",$F$4,IF(A10="CANALETE",$F$5,IF(A10="CERETE",$F$6,IF(A10="CHIMA",$F$7,IF(A10="CHINU",$F$8,IF(A10="CIENAGA DE ORO",$F$9,IF(A10="COTORRA",$F$10,IF(A10="LA APARTADA",$F$11,IF(A10="LORICA",$F$12,IF(A10="LOS CORDOBAS",$F$13,IF(A10="MOMIL",$F$14,IF(A10="MONTELIBANO",$F$15,IF(A10="MOÑITOS",$F$16,IF(A10="PLANETA RICA",$F$17,IF(A10="PUEBLO NUEVO",$F$18,IF(A10="PUERTO ESCONDIDO",$F$19,IF(A10="PUERTO LIBERTADOR",$F$20,IF(A10="PURISIMA",$F$21,IF(A10="SAHAGUN",$F$22,IF(A10="SAN ANDRES SOTAVENTO",$F$23,IF(A10="SAN ANTERO",$F$24,IF(A10="SAN BERNARDO DEL VIENTO",$F$25,IF(A10="SAN CARLOS",$F$26,IF(A10="SAN JOSE DE URE",$F$27,IF(A10="SAN PELAYO",$F$28,IF(A10="TIERRALTA",$F$29,IF(A10="TUCHIN",$F$30,IF(A10="VALENCIA",$F$31))))))))))))))))))))))))))))))) -> 15446 | D10: =IFERROR(B10/C10*$F$34,"0") -> 38.845008 | E10: COTORRA | F10: =IF($H$2=2022,POBLACIÓN!F14,POBLACIÓN!G14) -> 19845
A11: Lorica | B11: 100 | C11: =(IF(A11="MONTERIA",$F$2,IF(A11="AYAPEL",$F$3,IF(A11="BUENAVISTA",$F$4,IF(A11="CANALETE",$F$5,IF(A11="CERETE",$F$6,IF(A11="CHIMA",$F$7,IF(A11="CHINU",$F$8,IF(A11="CIENAGA DE ORO",$F$9,IF(A11="COTORRA",$F$10,IF(A11="LA APARTADA",$F$11,IF(A11="LORICA",$F$12,IF(A11="LOS CORDOBAS",$F$13,IF(A11="MOMIL",$F$14,IF(A11="MONTELIBANO",$F$15,IF(A11="MOÑITOS",$F$16,IF(A11="PLANETA RICA",$F$17,IF(A11="PUEBLO NUEVO",$F$18,IF(A11="PUERTO ESCONDIDO",$F$19,IF(A11="PUERTO LIBERTADOR",$F$20,IF(A11="PURISIMA",$F$21,IF(A11="SAHAGUN",$F$22,IF(A11="SAN ANDRES SOTAVENTO",$F$23,IF(A11="SAN ANTERO",$F$24,IF(A11="SAN BERNARDO DEL VIENTO",$F$25,IF(A11="SAN CARLOS",$F$26,IF(A11="SAN JOSE DE URE",$F$27,IF(A11="SAN PELAYO",$F$28,IF(A11="TIERRALTA",$F$29,IF(A11="TUCHIN",$F$30,IF(A11="VALENCIA",$F$31))))))))))))))))))))))))))))))) -> 117188 | D11: =IFERROR(B11/C11*$F$34,"0") -> 85.332969 | E11: LA APARTADA | F11: =IF($H$2=2022,POBLACIÓN!F15,POBLACIÓN!G15) -> 15446
A12: Los Cordobas | B12: 5 | C12: =(IF(A12="MONTERIA",$F$2,IF(A12="AYAPEL",$F$3,IF(A12="BUENAVISTA",$F$4,IF(A12="CANALETE",$F$5,IF(A12="CERETE",$F$6,IF(A12="CHIMA",$F$7,IF(A12="CHINU",$F$8,IF(A12="CIENAGA DE ORO",$F$9,IF(A12="COTORRA",$F$10,IF(A12="LA APARTADA",$F$11,IF(A12="LORICA",$F$12,IF(A12="LOS CORDOBAS",$F$13,IF(A12="MOMIL",$F$14,IF(A12="MONTELIBANO",$F$15,IF(A12="MOÑITOS",$F$16,IF(A12="PLANETA RICA",$F$17,IF(A12="PUEBLO NUEVO",$F$18,IF(A12="PUERTO ESCONDIDO",$F$19,IF(A12="PUERTO LIBERTADOR",$F$20,IF(A12="PURISIMA",$F$21,IF(A12="SAHAGUN",$F$22,IF(A12="SAN ANDRES SOTAVENTO",$F$23,IF(A12="SAN ANTERO",$F$24,IF(A12="SAN BERNARDO DEL VIENTO",$F$25,IF(A12="SAN CARLOS",$F$26,IF(A12="SAN JOSE DE URE",$F$27,IF(A12="SAN PELAYO",$F$28,IF(A12="TIERRALTA",$F$29,IF(A12="TUCHIN",$F$30,IF(A12="VALENCIA",$F$31))))))))))))))))))))))))))))))) -> 19607 | D12: =IFERROR(B12/C12*$F$34,"0") -> 25.501097 | E12: LORICA | F12: =IF($H$2=2022,POBLACIÓN!F16,POBLACIÓN!G16) -> 117188
A13: Momil | B13: 4 | C13: =(IF(A13="MONTERIA",$F$2,IF(A13="AYAPEL",$F$3,IF(A13="BUENAVISTA",$F$4,IF(A13="CANALETE",$F$5,IF(A13="CERETE",$F$6,IF(A13="CHIMA",$F$7,IF(A13="CHINU",$F$8,IF(A13="CIENAGA DE ORO",$F$9,IF(A13="COTORRA",$F$10,IF(A13="LA APARTADA",$F$11,IF(A13="LORICA",$F$12,IF(A13="LOS CORDOBAS",$F$13,IF(A13="MOMIL",$F$14,IF(A13="MONTELIBANO",$F$15,IF(A13="MOÑITOS",$F$16,IF(A13="PLANETA RICA",$F$17,IF(A13="PUEBLO NUEVO",$F$18,IF(A13="PUERTO ESCONDIDO",$F$19,IF(A13="PUERTO LIBERTADOR",$F$20,IF(A13="PURISIMA",$F$21,IF(A13="SAHAGUN",$F$22,IF(A13="SAN ANDRES SOTAVENTO",$F$23,IF(A13="SAN ANTERO",$F$24,IF(A13="SAN BERNARDO DEL VIENTO",$F$25,IF(A13="SAN CARLOS",$F$26,IF(A13="SAN JOSE DE URE",$F$27,IF(A13="SAN PELAYO",$F$28,IF(A13="TIERRALTA",$F$29,IF(A13="TUCHIN",$F$30,IF(A13="VALENCIA",$F$31))))))))))))))))))))))))))))))) -> 20422 | D13: =IFERROR(B13/C13*$F$34,"0") -> 19.58672 | E13: LOS CORDOBAS | F13: =IF($H$2=2022,POBLACIÓN!F17,POBLACIÓN!G17) -> 19607
A14: Montelibano | B14: 79 | C14: =(IF(A14="MONTERIA",$F$2,IF(A14="AYAPEL",$F$3,IF(A14="BUENAVISTA",$F$4,IF(A14="CANALETE",$F$5,IF(A14="CERETE",$F$6,IF(A14="CHIMA",$F$7,IF(A14="CHINU",$F$8,IF(A14="CIENAGA DE ORO",$F$9,IF(A14="COTORRA",$F$10,IF(A14="LA APARTADA",$F$11,IF(A14="LORICA",$F$12,IF(A14="LOS CORDOBAS",$F$13,IF(A14="MOMIL",$F$14,IF(A14="MONTELIBANO",$F$15,IF(A14="MOÑITOS",$F$16,IF(A14="PLANETA RICA",$F$17,IF(A14="PUEBLO NUEVO",$F$18,IF(A14="PUERTO ESCONDIDO",$F$19,IF(A14="PUERTO LIBERTADOR",$F$20,IF(A14="PURISIMA",$F$21,IF(A14="SAHAGUN",$F$22,IF(A14="SAN ANDRES SOTAVENTO",$F$23,IF(A14="SAN ANTERO",$F$24,IF(A14="SAN BERNARDO DEL VIENTO",$F$25,IF(A14="SAN CARLOS",$F$26,IF(A14="SAN JOSE DE URE",$F$27,IF(A14="SAN PELAYO",$F$28,IF(A14="TIERRALTA",$F$29,IF(A14="TUCHIN",$F$30,IF(A14="VALENCIA",$F$31))))))))))))))))))))))))))))))) -> 87187 | D14: =IFERROR(B14/C14*$F$34,"0") -> 90.609839 | E14: MOMIL | F14: =IF($H$2=2022,POBLACIÓN!F18,POBLACIÓN!G18) -> 20422
A15: Monteria | B15: 560 | C15: =(IF(A15="MONTERIA",$F$2,IF(A15="AYAPEL",$F$3,IF(A15="BUENAVISTA",$F$4,IF(A15="CANALETE",$F$5,IF(A15="CERETE",$F$6,IF(A15="CHIMA",$F$7,IF(A15="CHINU",$F$8,IF(A15="CIENAGA DE ORO",$F$9,IF(A15="COTORRA",$F$10,IF(A15="LA APARTADA",$F$11,IF(A15="LORICA",$F$12,IF(A15="LOS CORDOBAS",$F$13,IF(A15="MOMIL",$F$14,IF(A15="MONTELIBANO",$F$15,IF(A15="MOÑITOS",$F$16,IF(A15="PLANETA RICA",$F$17,IF(A15="PUEBLO NUEVO",$F$18,IF(A15="PUERTO ESCONDIDO",$F$19,IF(A15="PUERTO LIBERTADOR",$F$20,IF(A15="PURISIMA",$F$21,IF(A15="SAHAGUN",$F$22,IF(A15="SAN ANDRES SOTAVENTO",$F$23,IF(A15="SAN ANTERO",$F$24,IF(A15="SAN BERNARDO DEL VIENTO",$F$25,IF(A15="SAN CARLOS",$F$26,IF(A15="SAN JOSE DE URE",$F$27,IF(A15="SAN PELAYO",$F$28,IF(A15="TIERRALTA",$F$29,IF(A15="TUCHIN",$F$30,IF(A15="VALENCIA",$F$31))))))))))))))))))))))))))))))) -> 512994 | D15: =IFERROR(B15/C15*$F$34,"0") -> 109.16307 | E15: MONTELIBANO | F15: =IF($H$2=2022,POBLACIÓN!F19,POBLACIÓN!G19) -> 87187
A16: Moñitos | B16: 7 | C16: =(IF(A16="MONTERIA",$F$2,IF(A16="AYAPEL",$F$3,IF(A16="BUENAVISTA",$F$4,IF(A16="CANALETE",$F$5,IF(A16="CERETE",$F$6,IF(A16="CHIMA",$F$7,IF(A16="CHINU",$F$8,IF(A16="CIENAGA DE ORO",$F$9,IF(A16="COTORRA",$F$10,IF(A16="LA APARTADA",$F$11,IF(A16="LORICA",$F$12,IF(A16="LOS CORDOBAS",$F$13,IF(A16="MOMIL",$F$14,IF(A16="MONTELIBANO",$F$15,IF(A16="MOÑITOS",$F$16,IF(A16="PLANETA RICA",$F$17,IF(A16="PUEBLO NUEVO",$F$18,IF(A16="PUERTO ESCONDIDO",$F$19,IF(A16="PUERTO LIBERTADOR",$F$20,IF(A16="PURISIMA",$F$21,IF(A16="SAHAGUN",$F$22,IF(A16="SAN ANDRES SOTAVENTO",$F$23,IF(A16="SAN ANTERO",$F$24,IF(A16="SAN BERNARDO DEL VIENTO",$F$25,IF(A16="SAN CARLOS",$F$26,IF(A16="SAN JOSE DE URE",$F$27,IF(A16="SAN PELAYO",$F$28,IF(A16="TIERRALTA",$F$29,IF(A16="TUCHIN",$F$30,IF(A16="VALENCIA",$F$31))))))))))))))))))))))))))))))) -> 31047 | D16: =IFERROR(B16/C16*$F$34,"0") -> 22.546462 | E16: MOÑITOS | F16: =IF($H$2=2022,POBLACIÓN!F20,POBLACIÓN!G20) -> 31047
... A31: Valencia | B31: 3 | C31: =(IF(A31="MONTERIA",$F$2,IF(A31="AYAPEL",$F$3,IF(A31="BUENAVISTA",$F$4,IF(A31="CANALETE",$F$5,IF(A31="CERETE",$F$6,IF(A31="CHIMA",$F$7,IF(A31="CHINU",$F$8,IF(A31="CIENAGA DE ORO",$F$9,IF(A31="COTORRA",$F$10,IF(A31="LA APARTADA",$F$11,IF(A31="LORICA",$F$12,IF(A31="LOS CORDOBAS",$F$13,IF(A31="MOMIL",$F$14,IF(A31="MONTELIBANO",$F$15,IF(A31="MOÑITOS",$F$16,IF(A31="PLANETA RICA",$F$17,IF(A31="PUEBLO NUEVO",$F$18,IF(A31="PUERTO ESCONDIDO",$F$19,IF(A31="PUERTO LIBERTADOR",$F$20,IF(A31="PURISIMA",$F$21,IF(A31="SAHAGUN",$F$22,IF(A31="SAN ANDRES SOTAVENTO",$F$23,IF(A31="SAN ANTERO",$F$24,IF(A31="SAN BERNARDO DEL VIENTO",$F$25,IF(A31="SAN CARLOS",$F$26,IF(A31="SAN JOSE DE URE",$F$27,IF(A31="SAN PELAYO",$F$28,IF(A31="TIERRALTA",$F$29,IF(A31="TUCHIN",$F$30,IF(A31="VALENCIA",$F$31))))))))))))))))))))))))))))))) -> 36886 | D31: =IFERROR(B31/C31*$F$34,"0") -> 8.1331671 | E31: VALENCIA | F31: =IF($H$2=2022,POBLACIÓN!F35,POBLACIÓN!G35) -> 36886
A32: CÓRDOBA | B32: 1072 | C32: =F32 -> 1856496 | D32: =B32/C32*$F$34 -> 57.743189 | E32: CÓRDOBA | F32: =SUM(F2:F31) -> 1856496
A34: COEFICIENTE DE MULTIPLICACIÓN | F34: 100000

Sheet INCIDENCIA POR AREA
A1: MUNICIPIO | B1: CASOS | C1: POBLACIÓN TOTAL | D1: POBLACIÓN URBANA | E1: POBLACIÓN RURAL | F1: INCIDENCIA ACUMULADA TOTAL | G1: INCIDENCIA ACUMULADA URBANA | H1: INCIDENCIA ACUMULADA RURAL | J1: AÑO | L1: 2022 | N1: MUNICIPIOS | O1: POBLACIÓN TOTAL | P1: POBLACIÓN URBANA | Q1: POBLACIÓN RURAL | S1: 100
C2: =(IF(A2="MONTERIA",$O$2,IF(A2="AYAPEL",$O$3,IF(A2="BUENAVISTA",$O$4,IF(A2="CANALETE",$O$5,IF(A2="CERETE",$O$6,IF(A2="CHIMA",$O$7,IF(A2="CHINU",$O$8,IF(A2="CIENAGA DE ORO",$O$9,IF(A2="COTORRA",$O$10,IF(A2="LA APARTADA",$O$11,IF(A2="LORICA",$O$12,IF(A2="LOS CORDOBAS",$O$13,IF(A2="MOMIL",$O$14,IF(A2="MONTELIBANO",$O$15,IF(A2="MOÑITOS",$O$16,IF(A2="PLANETA RICA",$O$17,IF(A2="PUEBLO NUEVO",$O$18,IF(A2="PUERTO ESCONDIDO",$O$19,IF(A2="PUERTO LIBERTADOR",$O$20,IF(A2="PURISIMA",$O$21,IF(A2="SAHAGUN",$O$22,IF(A2="SAN ANDRES SOTAVENTO",$O$23,IF(A2="SAN ANTERO",$O$24,IF(A2="SAN BERNARDO DEL VIENTO",$O$25,IF(A2="SAN CARLOS",$O$26,IF(A2="SAN JOSE DE URE",$O$27,IF(A2="SAN PELAYO",$O$28,IF(A2="TIERRALTA",$O$29,IF(A2="TUCHIN",$O$30,IF(A2="VALENCIA",$O$31))))))))))))))))))))))))))))))) -> FALSE | D2: =(IF(A2="MONTERIA",$P$2,IF(A2="AYAPEL",$P$3,IF(A2="BUENAVISTA",$P$4,IF(A2="CANALETE",$P$5,IF(A2="CERETE",$P$6,IF(A2="CHIMA",$P$7,IF(A2="CHINU",$P$8,IF(A2="CIENAGA DE ORO",$P$9,IF(A2="COTORRA",$P$10,IF(A2="LA APARTADA",$P$11,IF(A2="LORICA",$P$12,IF(A2="LOS CORDOBAS",$P$13,IF(A2="MOMIL",$P$14,IF(A2="MONTELIBANO",$P$15,IF(A2="MOÑITOS",$P$16,IF(A2="PLANETA RICA",$P$17,IF(A2="PUEBLO NUEVO",$P$18,IF(A2="PUERTO ESCONDIDO",$P$19,IF(A2="PUERTO LIBERTADOR",$P$20,IF(A2="PURISIMA",$P$21,IF(A2="SAHAGUN",$P$22,IF(A2="SAN ANDRES SOTAVENTO",$P$23,IF(A2="SAN ANTERO",$P$24,IF(A2="SAN BERNARDO DEL VIENTO",$P$25,IF(A2="SAN CARLOS",$P$26,IF(A2="SAN JOSE DE URE",$P$27,IF(A2="SAN PELAYO",$P$28,IF(A2="TIERRALTA",$P$29,IF(A2="TUCHIN",$P$30,IF(A2="VALENCIA",$P$31))))))))))))))))))))))))))))))) -> FALSE | E2: =(IF(A2="MONTERIA",$Q$2,IF(A2="AYAPEL",$Q$3,IF(A2="BUENAVISTA",$Q$4,IF(A2="CANALETE",$Q$5,IF(A2="CERETE",$Q$6,IF(A2="CHIMA",$Q$7,IF(A2="CHINU",$Q$8,IF(A2="CIENAGA DE ORO",$Q$9,IF(A2="COTORRA",$Q$10,IF(A2="LA APARTADA",$Q$11,IF(A2="LORICA",$Q$12,IF(A2="LOS CORDOBAS",$Q$13,IF(A2="MOMIL",$Q$14,IF(A2="MONTELIBANO",$Q$15,IF(A2="MOÑITOS",$Q$16,IF(A2="PLANETA RICA",$Q$17,IF(A2="PUEBLO NUEVO",$Q$18,IF(A2="PUERTO ESCONDIDO",$Q$19,IF(A2="PUERTO LIBERTADOR",$Q$20,IF(A2="PURISIMA",$Q$21,IF(A2="SAHAGUN",$Q$22,IF(A2="SAN ANDRES SOTAVENTO",$Q$23,IF(A2="SAN ANTERO",$Q$24,IF(A2="SAN BERNARDO DEL VIENTO",$Q$25,IF(A2="SAN CARLOS",$Q$26,IF(A2="SAN JOSE DE URE",$Q$27,IF(A2="SAN PELAYO",$Q$28,IF(A2="TIERRALTA",$Q$29,IF(A2="TUCHIN",$Q$30,IF(A2="VALENCIA",$Q$31))))))))))))))))))))))))))))))) -> FALSE | F2: =IFERROR(B2/C2*$H$34,"0") -> 0 | G2: =IFERROR(B2/D2*$H$34,"0") -> 0 | H2: =IFERROR(B2/E2*$H$34,"0") -> 0 | J2: 2022 | L2: 2023 | N2: MONTERIA | O2: =IF($J$2=2022,POBLACIÓN!F6,POBLACIÓN!G6) -> 512994 | P2: =IF($J$2=2022,POBLACIÓN!I6,POBLACIÓN!J6) -> 400073 | Q2: =IF($J$2=2022,POBLACIÓN!L6,POBLACIÓN!M6) -> 112921 | S2: 1000
C3: =(IF(A3="MONTERIA",$O$2,IF(A3="AYAPEL",$O$3,IF(A3="BUENAVISTA",$O$4,IF(A3="CANALETE",$O$5,IF(A3="CERETE",$O$6,IF(A3="CHIMA",$O$7,IF(A3="CHINU",$O$8,IF(A3="CIENAGA DE ORO",$O$9,IF(A3="COTORRA",$O$10,IF(A3="LA APARTADA",$O$11,IF(A3="LORICA",$O$12,IF(A3="LOS CORDOBAS",$O$13,IF(A3="MOMIL",$O$14,IF(A3="MONTELIBANO",$O$15,IF(A3="MOÑITOS",$O$16,IF(A3="PLANETA RICA",$O$17,IF(A3="PUEBLO NUEVO",$O$18,IF(A3="PUERTO ESCONDIDO",$O$19,IF(A3="PUERTO LIBERTADOR",$O$20,IF(A3="PURISIMA",$O$21,IF(A3="SAHAGUN",$O$22,IF(A3="SAN ANDRES SOTAVENTO",$O$23,IF(A3="SAN ANTERO",$O$24,IF(A3="SAN BERNARDO DEL VIENTO",$O$25,IF(A3="SAN CARLOS",$O$26,IF(A3="SAN JOSE DE URE",$O$27,IF(A3="SAN PELAYO",$O$28,IF(A3="TIERRALTA",$O$29,IF(A3="TUCHIN",$O$30,IF(A3="VALENCIA",$O$31))))))))))))))))))))))))))))))) -> FALSE | D3: =(IF(A3="MONTERIA",$P$2,IF(A3="AYAPEL",$P$3,IF(A3="BUENAVISTA",$P$4,IF(A3="CANALETE",$P$5,IF(A3="CERETE",$P$6,IF(A3="CHIMA",$P$7,IF(A3="CHINU",$P$8,IF(A3="CIENAGA DE ORO",$P$9,IF(A3="COTORRA",$P$10,IF(A3="LA APARTADA",$P$11,IF(A3="LORICA",$P$12,IF(A3="LOS CORDOBAS",$P$13,IF(A3="MOMIL",$P$14,IF(A3="MONTELIBANO",$P$15,IF(A3="MOÑITOS",$P$16,IF(A3="PLANETA RICA",$P$17,IF(A3="PUEBLO NUEVO",$P$18,IF(A3="PUERTO ESCONDIDO",$P$19,IF(A3="PUERTO LIBERTADOR",$P$20,IF(A3="PURISIMA",$P$21,IF(A3="SAHAGUN",$P$22,IF(A3="SAN ANDRES SOTAVENTO",$P$23,IF(A3="SAN ANTERO",$P$24,IF(A3="SAN BERNARDO DEL VIENTO",$P$25,IF(A3="SAN CARLOS",$P$26,IF(A3="SAN JOSE DE URE",$P$27,IF(A3="SAN PELAYO",$P$28,IF(A3="TIERRALTA",$P$29,IF(A3="TUCHIN",$P$30,IF(A3="VALENCIA",$P$31))))))))))))))))))))))))))))))) -> FALSE | E3: =(IF(A3="MONTERIA",$Q$2,IF(A3="AYAPEL",$Q$3,IF(A3="BUENAVISTA",$Q$4,IF(A3="CANALETE",$Q$5,IF(A3="CERETE",$Q$6,IF(A3="CHIMA",$Q$7,IF(A3="CHINU",$Q$8,IF(A3="CIENAGA DE ORO",$Q$9,IF(A3="COTORRA",$Q$10,IF(A3="LA APARTADA",$Q$11,IF(A3="LORICA",$Q$12,IF(A3="LOS CORDOBAS",$Q$13,IF(A3="MOMIL",$Q$14,IF(A3="MONTELIBANO",$Q$15,IF(A3="MOÑITOS",$Q$16,IF(A3="PLANETA RICA",$Q$17,IF(A3="PUEBLO NUEVO",$Q$18,IF(A3="PUERTO ESCONDIDO",$Q$19,IF(A3="PUERTO LIBERTADOR",$Q$20,IF(A3="PURISIMA",$Q$21,IF(A3="SAHAGUN",$Q$22,IF(A3="SAN ANDRES SOTAVENTO",$Q$23,IF(A3="SAN ANTERO",$Q$24,IF(A3="SAN BERNARDO DEL VIENTO",$Q$25,IF(A3="SAN CARLOS",$Q$26,IF(A3="SAN JOSE DE URE",$Q$27,IF(A3="SAN PELAYO",$Q$28,IF(A3="TIERRALTA",$Q$29,IF(A3="TUCHIN",$Q$30,IF(A3="VALENCIA",$Q$31))))))))))))))))))))))))))))))) -> FALSE | F3: =IFERROR(B3/C3*$H$34,"0") -> 0 | G3: =IFERROR(B3/D3*$H$34,"0") -> 0 | H3: =IFERROR(B3/E3*$H$34,"0") -> 0 | N3: AYAPEL | O3: =IF($J$2=2022,POBLACIÓN!F7,POBLACIÓN!G7) -> 47954 | P3: =IF($J$2=2022,POBLACIÓN!I7,POBLACIÓN!J7) -> 27949 | Q3: =IF($J$2=2022,POBLACIÓN!L7,POBLACIÓN!M7) -> 20005 | S3: 10000
C4: =(IF(A4="MONTERIA",$O$2,IF(A4="AYAPEL",$O$3,IF(A4="BUENAVISTA",$O$4,IF(A4="CANALETE",$O$5,IF(A4="CERETE",$O$6,IF(A4="CHIMA",$O$7,IF(A4="CHINU",$O$8,IF(A4="CIENAGA DE ORO",$O$9,IF(A4="COTORRA",$O$10,IF(A4="LA APARTADA",$O$11,IF(A4="LORICA",$O$12,IF(A4="LOS CORDOBAS",$O$13,IF(A4="MOMIL",$O$14,IF(A4="MONTELIBANO",$O$15,IF(A4="MOÑITOS",$O$16,IF(A4="PLANETA RICA",$O$17,IF(A4="PUEBLO NUEVO",$O$18,IF(A4="PUERTO ESCONDIDO",$O$19,IF(A4="PUERTO LIBERTADOR",$O$20,IF(A4="PURISIMA",$O$21,IF(A4="SAHAGUN",$O$22,IF(A4="SAN ANDRES SOTAVENTO",$O$23,IF(A4="SAN ANTERO",$O$24,IF(A4="SAN BERNARDO DEL VIENTO",$O$25,IF(A4="SAN CARLOS",$O$26,IF(A4="SAN JOSE DE URE",$O$27,IF(A4="SAN PELAYO",$O$28,IF(A4="TIERRALTA",$O$29,IF(A4="TUCHIN",$O$30,IF(A4="VALENCIA",$O$31))))))))))))))))))))))))))))))) -> FALSE | D4: =(IF(A4="MONTERIA",$P$2,IF(A4="AYAPEL",$P$3,IF(A4="BUENAVISTA",$P$4,IF(A4="CANALETE",$P$5,IF(A4="CERETE",$P$6,IF(A4="CHIMA",$P$7,IF(A4="CHINU",$P$8,IF(A4="CIENAGA DE ORO",$P$9,IF(A4="COTORRA",$P$10,IF(A4="LA APARTADA",$P$11,IF(A4="LORICA",$P$12,IF(A4="LOS CORDOBAS",$P$13,IF(A4="MOMIL",$P$14,IF(A4="MONTELIBANO",$P$15,IF(A4="MOÑITOS",$P$16,IF(A4="PLANETA RICA",$P$17,IF(A4="PUEBLO NUEVO",$P$18,IF(A4="PUERTO ESCONDIDO",$P$19,IF(A4="PUERTO LIBERTADOR",$P$20,IF(A4="PURISIMA",$P$21,IF(A4="SAHAGUN",$P$22,IF(A4="SAN ANDRES SOTAVENTO",$P$23,IF(A4="SAN ANTERO",$P$24,IF(A4="SAN BERNARDO DEL VIENTO",$P$25,IF(A4="SAN CARLOS",$P$26,IF(A4="SAN JOSE DE URE",$P$27,IF(A4="SAN PELAYO",$P$28,IF(A4="TIERRALTA",$P$29,IF(A4="TUCHIN",$P$30,IF(A4="VALENCIA",$P$31))))))))))))))))))))))))))))))) -> FALSE | E4: =(IF(A4="MONTERIA",$Q$2,IF(A4="AYAPEL",$Q$3,IF(A4="BUENAVISTA",$Q$4,IF(A4="CANALETE",$Q$5,IF(A4="CERETE",$Q$6,IF(A4="CHIMA",$Q$7,IF(A4="CHINU",$Q$8,IF(A4="CIENAGA DE ORO",$Q$9,IF(A4="COTORRA",$Q$10,IF(A4="LA APARTADA",$Q$11,IF(A4="LORICA",$Q$12,IF(A4="LOS CORDOBAS",$Q$13,IF(A4="MOMIL",$Q$14,IF(A4="MONTELIBANO",$Q$15,IF(A4="MOÑITOS",$Q$16,IF(A4="PLANETA RICA",$Q$17,IF(A4="PUEBLO NUEVO",$Q$18,IF(A4="PUERTO ESCONDIDO",$Q$19,IF(A4="PUERTO LIBERTADOR",$Q$20,IF(A4="PURISIMA",$Q$21,IF(A4="SAHAGUN",$Q$22,IF(A4="SAN ANDRES SOTAVENTO",$Q$23,IF(A4="SAN ANTERO",$Q$24,IF(A4="SAN BERNARDO DEL VIENTO",$Q$25,IF(A4="SAN CARLOS",$Q$26,IF(A4="SAN JOSE DE URE",$Q$27,IF(A4="SAN PELAYO",$Q$28,IF(A4="TIERRALTA",$Q$29,IF(A4="TUCHIN",$Q$30,IF(A4="VALENCIA",$Q$31))))))))))))))))))))))))))))))) -> FALSE | F4: =IFERROR(B4/C4*$H$34,"0") -> 0 | G4: =IFERROR(B4/D4*$H$34,"0") -> 0 | H4: =IFERROR(B4/E4*$H$34,"0") -> 0 | N4: BUENAVISTA | O4: =IF($J$2=2022,POBLACIÓN!F8,POBLACIÓN!G8) -> 21772 | P4: =IF($J$2=2022,POBLACIÓN!I8,POBLACIÓN!J8) -> 7870 | Q4: =IF($J$2=2022,POBLACIÓN!L8,POBLACIÓN!M8) -> 13902 | S4: 100000
C5: =(IF(A5="MONTERIA",$O$2,IF(A5="AYAPEL",$O$3,IF(A5="BUENAVISTA",$O$4,IF(A5="CANALETE",$O$5,IF(A5="CERETE",$O$6,IF(A5="CHIMA",$O$7,IF(A5="CHINU",$O$8,IF(A5="CIENAGA DE ORO",$O$9,IF(A5="COTORRA",$O$10,IF(A5="LA APARTADA",$O$11,IF(A5="LORICA",$O$12,IF(A5="LOS CORDOBAS",$O$13,IF(A5="MOMIL",$O$14,IF(A5="MONTELIBANO",$O$15,IF(A5="MOÑITOS",$O$16,IF(A5="PLANETA RICA",$O$17,IF(A5="PUEBLO NUEVO",$O$18,IF(A5="PUERTO ESCONDIDO",$O$19,IF(A5="PUERTO LIBERTADOR",$O$20,IF(A5="PURISIMA",$O$21,IF(A5="SAHAGUN",$O$22,IF(A5="SAN ANDRES SOTAVENTO",$O$23,IF(A5="SAN ANTERO",$O$24,IF(A5="SAN BERNARDO DEL VIENTO",$O$25,IF(A5="SAN CARLOS",$O$26,IF(A5="SAN JOSE DE URE",$O$27,IF(A5="SAN PELAYO",$O$28,IF(A5="TIERRALTA",$O$29,IF(A5="TUCHIN",$O$30,IF(A5="VALENCIA",$O$31))))))))))))))))))))))))))))))) -> FALSE | D5: =(IF(A5="MONTERIA",$P$2,IF(A5="AYAPEL",$P$3,IF(A5="BUENAVISTA",$P$4,IF(A5="CANALETE",$P$5,IF(A5="CERETE",$P$6,IF(A5="CHIMA",$P$7,IF(A5="CHINU",$P$8,IF(A5="CIENAGA DE ORO",$P$9,IF(A5="COTORRA",$P$10,IF(A5="LA APARTADA",$P$11,IF(A5="LORICA",$P$12,IF(A5="LOS CORDOBAS",$P$13,IF(A5="MOMIL",$P$14,IF(A5="MONTELIBANO",$P$15,IF(A5="MOÑITOS",$P$16,IF(A5="PLANETA RICA",$P$17,IF(A5="PUEBLO NUEVO",$P$18,IF(A5="PUERTO ESCONDIDO",$P$19,IF(A5="PUERTO LIBERTADOR",$P$20,IF(A5="PURISIMA",$P$21,IF(A5="SAHAGUN",$P$22,IF(A5="SAN ANDRES SOTAVENTO",$P$23,IF(A5="SAN ANTERO",$P$24,IF(A5="SAN BERNARDO DEL VIENTO",$P$25,IF(A5="SAN CARLOS",$P$26,IF(A5="SAN JOSE DE URE",$P$27,IF(A5="SAN PELAYO",$P$28,IF(A5="TIERRALTA",$P$29,IF(A5="TUCHIN",$P$30,IF(A5="VALENCIA",$P$31))))))))))))))))))))))))))))))) -> FALSE | E5: =(IF(A5="MONTERIA",$Q$2,IF(A5="AYAPEL",$Q$3,IF(A5="BUENAVISTA",$Q$4,IF(A5="CANALETE",$Q$5,IF(A5="CERETE",$Q$6,IF(A5="CHIMA",$Q$7,IF(A5="CHINU",$Q$8,IF(A5="CIENAGA DE ORO",$Q$9,IF(A5="COTORRA",$Q$10,IF(A5="LA APARTADA",$Q$11,IF(A5="LORICA",$Q$12,IF(A5="LOS CORDOBAS",$Q$13,IF(A5="MOMIL",$Q$14,IF(A5="MONTELIBANO",$Q$15,IF(A5="MOÑITOS",$Q$16,IF(A5="PLANETA RICA",$Q$17,IF(A5="PUEBLO NUEVO",$Q$18,IF(A5="PUERTO ESCONDIDO",$Q$19,IF(A5="PUERTO LIBERTADOR",$Q$20,IF(A5="PURISIMA",$Q$21,IF(A5="SAHAGUN",$Q$22,IF(A5="SAN ANDRES SOTAVENTO",$Q$23,IF(A5="SAN ANTERO",$Q$24,IF(A5="SAN BERNARDO DEL VIENTO",$Q$25,IF(A5="SAN CARLOS",$Q$26,IF(A5="SAN JOSE DE URE",$Q$27,IF(A5="SAN PELAYO",$Q$28,IF(A5="TIERRALTA",$Q$29,IF(A5="TUCHIN",$Q$30,IF(A5="VALENCIA",$Q$31))))))))))))))))))))))))))))))) -> FALSE | F5: =IFERROR(B5/C5*$H$34,"0") -> 0 | G5: =IFERROR(B5/D5*$H$34,"0") -> 0 | H5: =IFERROR(B5/E5*$H$34,"0") -> 0 | N5: CANALETE | O5: =IF($J$2=2022,POBLACIÓN!F9,POBLACIÓN!G9) -> 15668 | P5: =IF($J$2=2022,POBLACIÓN!I9,POBLACIÓN!J9) -> 3862 | Q5: =IF($J$2=2022,POBLACIÓN!L9,POBLACIÓN!M9) -> 11806
C6: =(IF(A6="MONTERIA",$O$2,IF(A6="AYAPEL",$O$3,IF(A6="BUENAVISTA",$O$4,IF(A6="CANALETE",$O$5,IF(A6="CERETE",$O$6,IF(A6="CHIMA",$O$7,IF(A6="CHINU",$O$8,IF(A6="CIENAGA DE ORO",$O$9,IF(A6="COTORRA",$O$10,IF(A6="LA APARTADA",$O$11,IF(A6="LORICA",$O$12,IF(A6="LOS CORDOBAS",$O$13,IF(A6="MOMIL",$O$14,IF(A6="MONTELIBANO",$O$15,IF(A6="MOÑITOS",$O$16,IF(A6="PLANETA RICA",$O$17,IF(A6="PUEBLO NUEVO",$O$18,IF(A6="PUERTO ESCONDIDO",$O$19,IF(A6="PUERTO LIBERTADOR",$O$20,IF(A6="PURISIMA",$O$21,IF(A6="SAHAGUN",$O$22,IF(A6="SAN ANDRES SOTAVENTO",$O$23,IF(A6="SAN ANTERO",$O$24,IF(A6="SAN BERNARDO DEL VIENTO",$O$25,IF(A6="SAN CARLOS",$O$26,IF(A6="SAN JOSE DE URE",$O$27,IF(A6="SAN PELAYO",$O$28,IF(A6="TIERRALTA",$O$29,IF(A6="TUCHIN",$O$30,IF(A6="VALENCIA",$O$31))))))))))))))))))))))))))))))) -> FALSE | D6: =(IF(A6="MONTERIA",$P$2,IF(A6="AYAPEL",$P$3,IF(A6="BUENAVISTA",$P$4,IF(A6="CANALETE",$P$5,IF(A6="CERETE",$P$6,IF(A6="CHIMA",$P$7,IF(A6="CHINU",$P$8,IF(A6="CIENAGA DE ORO",$P$9,IF(A6="COTORRA",$P$10,IF(A6="LA APARTADA",$P$11,IF(A6="LORICA",$P$12,IF(A6="LOS CORDOBAS",$P$13,IF(A6="MOMIL",$P$14,IF(A6="MONTELIBANO",$P$15,IF(A6="MOÑITOS",$P$16,IF(A6="PLANETA RICA",$P$17,IF(A6="PUEBLO NUEVO",$P$18,IF(A6="PUERTO ESCONDIDO",$P$19,IF(A6="PUERTO LIBERTADOR",$P$20,IF(A6="PURISIMA",$P$21,IF(A6="SAHAGUN",$P$22,IF(A6="SAN ANDRES SOTAVENTO",$P$23,IF(A6="SAN ANTERO",$P$24,IF(A6="SAN BERNARDO DEL VIENTO",$P$25,IF(A6="SAN CARLOS",$P$26,IF(A6="SAN JOSE DE URE",$P$27,IF(A6="SAN PELAYO",$P$28,IF(A6="TIERRALTA",$P$29,IF(A6="TUCHIN",$P$30,IF(A6="VALENCIA",$P$31))))))))))))))))))))))))))))))) -> FALSE | E6: =(IF(A6="MONTERIA",$Q$2,IF(A6="AYAPEL",$Q$3,IF(A6="BUENAVISTA",$Q$4,IF(A6="CANALETE",$Q$5,IF(A6="CERETE",$Q$6,IF(A6="CHIMA",$Q$7,IF(A6="CHINU",$Q$8,IF(A6="CIENAGA DE ORO",$Q$9,IF(A6="COTORRA",$Q$10,IF(A6="LA APARTADA",$Q$11,IF(A6="LORICA",$Q$12,IF(A6="LOS CORDOBAS",$Q$13,IF(A6="MOMIL",$Q$14,IF(A6="MONTELIBANO",$Q$15,IF(A6="MOÑITOS",$Q$16,IF(A6="PLANETA RICA",$Q$17,IF(A6="PUEBLO NUEVO",$Q$18,IF(A6="PUERTO ESCONDIDO",$Q$19,IF(A6="PUERTO LIBERTADOR",$Q$20,IF(A6="PURISIMA",$Q$21,IF(A6="SAHAGUN",$Q$22,IF(A6="SAN ANDRES SOTAVENTO",$Q$23,IF(A6="SAN ANTERO",$Q$24,IF(A6="SAN BERNARDO DEL VIENTO",$Q$25,IF(A6="SAN CARLOS",$Q$26,IF(A6="SAN JOSE DE URE",$Q$27,IF(A6="SAN PELAYO",$Q$28,IF(A6="TIERRALTA",$Q$29,IF(A6="TUCHIN",$Q$30,IF(A6="VALENCIA",$Q$31))))))))))))))))))))))))))))))) -> FALSE | F6: =IFERROR(B6/C6*$H$34,"0") -> 0 | G6: =IFERROR(B6/D6*$H$34,"0") -> 0 | H6: =IFERROR(B6/E6*$H$34,"0") -> 0 | N6: CERETE | O6: =IF($J$2=2022,POBLACIÓN!F10,POBLACIÓN!G10) -> 110032 | P6: =IF($J$2=2022,POBLACIÓN!I10,POBLACIÓN!J10) -> 60639 | Q6: =IF($J$2=2022,POBLACIÓN!L10,POBLACIÓN!M10) -> 49393
C7: =(IF(A7="MONTERIA",$O$2,IF(A7="AYAPEL",$O$3,IF(A7="BUENAVISTA",$O$4,IF(A7="CANALETE",$O$5,IF(A7="CERETE",$O$6,IF(A7="CHIMA",$O$7,IF(A7="CHINU",$O$8,IF(A7="CIENAGA DE ORO",$O$9,IF(A7="COTORRA",$O$10,IF(A7="LA APARTADA",$O$11,IF(A7="LORICA",$O$12,IF(A7="LOS CORDOBAS",$O$13,IF(A7="MOMIL",$O$14,IF(A7="MONTELIBANO",$O$15,IF(A7="MOÑITOS",$O$16,IF(A7="PLANETA RICA",$O$17,IF(A7="PUEBLO NUEVO",$O$18,IF(A7="PUERTO ESCONDIDO",$O$19,IF(A7="PUERTO LIBERTADOR",$O$20,IF(A7="PURISIMA",$O$21,IF(A7="SAHAGUN",$O$22,IF(A7="SAN ANDRES SOTAVENTO",$O$23,IF(A7="SAN ANTERO",$O$24,IF(A7="SAN BERNARDO DEL VIENTO",$O$25,IF(A7="SAN CARLOS",$O$26,IF(A7="SAN JOSE DE URE",$O$27,IF(A7="SAN PELAYO",$O$28,IF(A7="TIERRALTA",$O$29,IF(A7="TUCHIN",$O$30,IF(A7="VALENCIA",$O$31))))))))))))))))))))))))))))))) -> FALSE | D7: =(IF(A7="MONTERIA",$P$2,IF(A7="AYAPEL",$P$3,IF(A7="BUENAVISTA",$P$4,IF(A7="CANALETE",$P$5,IF(A7="CERETE",$P$6,IF(A7="CHIMA",$P$7,IF(A7="CHINU",$P$8,IF(A7="CIENAGA DE ORO",$P$9,IF(A7="COTORRA",$P$10,IF(A7="LA APARTADA",$P$11,IF(A7="LORICA",$P$12,IF(A7="LOS CORDOBAS",$P$13,IF(A7="MOMIL",$P$14,IF(A7="MONTELIBANO",$P$15,IF(A7="MOÑITOS",$P$16,IF(A7="PLANETA RICA",$P$17,IF(A7="PUEBLO NUEVO",$P$18,IF(A7="PUERTO ESCONDIDO",$P$19,IF(A7="PUERTO LIBERTADOR",$P$20,IF(A7="PURISIMA",$P$21,IF(A7="SAHAGUN",$P$22,IF(A7="SAN ANDRES SOTAVENTO",$P$23,IF(A7="SAN ANTERO",$P$24,IF(A7="SAN BERNARDO DEL VIENTO",$P$25,IF(A7="SAN CARLOS",$P$26,IF(A7="SAN JOSE DE URE",$P$27,IF(A7="SAN PELAYO",$P$28,IF(A7="TIERRALTA",$P$29,IF(A7="TUCHIN",$P$30,IF(A7="VALENCIA",$P$31))))))))))))))))))))))))))))))) -> FALSE | E7: =(IF(A7="MONTERIA",$Q$2,IF(A7="AYAPEL",$Q$3,IF(A7="BUENAVISTA",$Q$4,IF(A7="CANALETE",$Q$5,IF(A7="CERETE",$Q$6,IF(A7="CHIMA",$Q$7,IF(A7="CHINU",$Q$8,IF(A7="CIENAGA DE ORO",$Q$9,IF(A7="COTORRA",$Q$10,IF(A7="LA APARTADA",$Q$11,IF(A7="LORICA",$Q$12,IF(A7="LOS CORDOBAS",$Q$13,IF(A7="MOMIL",$Q$14,IF(A7="MONTELIBANO",$Q$15,IF(A7="MOÑITOS",$Q$16,IF(A7="PLANETA RICA",$Q$17,IF(A7="PUEBLO NUEVO",$Q$18,IF(A7="PUERTO ESCONDIDO",$Q$19,IF(A7="PUERTO LIBERTADOR",$Q$20,IF(A7="PURISIMA",$Q$21,IF(A7="SAHAGUN",$Q$22,IF(A7="SAN ANDRES SOTAVENTO",$Q$23,IF(A7="SAN ANTERO",$Q$24,IF(A7="SAN BERNARDO DEL VIENTO",$Q$25,IF(A7="SAN CARLOS",$Q$26,IF(A7="SAN JOSE DE URE",$Q$27,IF(A7="SAN PELAYO",$Q$28,IF(A7="TIERRALTA",$Q$29,IF(A7="TUCHIN",$Q$30,IF(A7="VALENCIA",$Q$31))))))))))))))))))))))))))))))) -> FALSE | F7: =IFERROR(B7/C7*$H$34,"0") -> 0 | G7: =IFERROR(B7/D7*$H$34,"0") -> 0 | H7: =IFERROR(B7/E7*$H$34,"0") -> 0 | N7: CHIMA | O7: =IF($J$2=2022,POBLACIÓN!F11,POBLACIÓN!G11) -> 18173 | P7: =IF($J$2=2022,POBLACIÓN!I11,POBLACIÓN!J11) -> 3691 | Q7: =IF($J$2=2022,POBLACIÓN!L11,POBLACIÓN!M11) -> 14482
C8: =(IF(A8="MONTERIA",$O$2,IF(A8="AYAPEL",$O$3,IF(A8="BUENAVISTA",$O$4,IF(A8="CANALETE",$O$5,IF(A8="CERETE",$O$6,IF(A8="CHIMA",$O$7,IF(A8="CHINU",$O$8,IF(A8="CIENAGA DE ORO",$O$9,IF(A8="COTORRA",$O$10,IF(A8="LA APARTADA",$O$11,IF(A8="LORICA",$O$12,IF(A8="LOS CORDOBAS",$O$13,IF(A8="MOMIL",$O$14,IF(A8="MONTELIBANO",$O$15,IF(A8="MOÑITOS",$O$16,IF(A8="PLANETA RICA",$O$17,IF(A8="PUEBLO NUEVO",$O$18,IF(A8="PUERTO ESCONDIDO",$O$19,IF(A8="PUERTO LIBERTADOR",$O$20,IF(A8="PURISIMA",$O$21,IF(A8="SAHAGUN",$O$22,IF(A8="SAN ANDRES SOTAVENTO",$O$23,IF(A8="SAN ANTERO",$O$24,IF(A8="SAN BERNARDO DEL VIENTO",$O$25,IF(A8="SAN CARLOS",$O$26,IF(A8="SAN JOSE DE URE",$O$27,IF(A8="SAN PELAYO",$O$28,IF(A8="TIERRALTA",$O$29,IF(A8="TUCHIN",$O$30,IF(A8="VALENCIA",$O$31))))))))))))))))))))))))))))))) -> FALSE | D8: =(IF(A8="MONTERIA",$P$2,IF(A8="AYAPEL",$P$3,IF(A8="BUENAVISTA",$P$4,IF(A8="CANALETE",$P$5,IF(A8="CERETE",$P$6,IF(A8="CHIMA",$P$7,IF(A8="CHINU",$P$8,IF(A8="CIENAGA DE ORO",$P$9,IF(A8="COTORRA",$P$10,IF(A8="LA APARTADA",$P$11,IF(A8="LORICA",$P$12,IF(A8="LOS CORDOBAS",$P$13,IF(A8="MOMIL",$P$14,IF(A8="MONTELIBANO",$P$15,IF(A8="MOÑITOS",$P$16,IF(A8="PLANETA RICA",$P$17,IF(A8="PUEBLO NUEVO",$P$18,IF(A8="PUERTO ESCONDIDO",$P$19,IF(A8="PUERTO LIBERTADOR",$P$20,IF(A8="PURISIMA",$P$21,IF(A8="SAHAGUN",$P$22,IF(A8="SAN ANDRES SOTAVENTO",$P$23,IF(A8="SAN ANTERO",$P$24,IF(A8="SAN BERNARDO DEL VIENTO",$P$25,IF(A8="SAN CARLOS",$P$26,IF(A8="SAN JOSE DE URE",$P$27,IF(A8="SAN PELAYO",$P$28,IF(A8="TIERRALTA",$P$29,IF(A8="TUCHIN",$P$30,IF(A8="VALENCIA",$P$31))))))))))))))))))))))))))))))) -> FALSE | E8: =(IF(A8="MONTERIA",$Q$2,IF(A8="AYAPEL",$Q$3,IF(A8="BUENAVISTA",$Q$4,IF(A8="CANALETE",$Q$5,IF(A8="CERETE",$Q$6,IF(A8="CHIMA",$Q$7,IF(A8="CHINU",$Q$8,IF(A8="CIENAGA DE ORO",$Q$9,IF(A8="COTORRA",$Q$10,IF(A8="LA APARTADA",$Q$11,IF(A8="LORICA",$Q$12,IF(A8="LOS CORDOBAS",$Q$13,IF(A8="MOMIL",$Q$14,IF(A8="MONTELIBANO",$Q$15,IF(A8="MOÑITOS",$Q$16,IF(A8="PLANETA RICA",$Q$17,IF(A8="PUEBLO NUEVO",$Q$18,IF(A8="PUERTO ESCONDIDO",$Q$19,IF(A8="PUERTO LIBERTADOR",$Q$20,IF(A8="PURISIMA",$Q$21,IF(A8="SAHAGUN",$Q$22,IF(A8="SAN ANDRES SOTAVENTO",$Q$23,IF(A8="SAN ANTERO",$Q$24,IF(A8="SAN BERNARDO DEL VIENTO",$Q$25,IF(A8="SAN CARLOS",$Q$26,IF(A8="SAN JOSE DE URE",$Q$27,IF(A8="SAN PELAYO",$Q$28,IF(A8="TIERRALTA",$Q$29,IF(A8="TUCHIN",$Q$30,IF(A8="VALENCIA",$Q$31))))))))))))))))))))))))))))))) -> FALSE | F8: =IFERROR(B8/C8*$H$34,"0") -> 0 | G8: =IFERROR(B8/D8*$H$34,"0") -> 0 | H8: =IFERROR(B8/E8*$H$34,"0") -> 0 | N8: CHINU | O8: =IF($J$2=2022,POBLACIÓN!F12,POBLACIÓN!G12) -> 49422 | P8: =IF($J$2=2022,POBLACIÓN!I12,POBLACIÓN!J12) -> 20022 | Q8: =IF($J$2=2022,POBLACIÓN!L12,POBLACIÓN!M12) -> 29400
C9: =(IF(A9="MONTERIA",$O$2,IF(A9="AYAPEL",$O$3,IF(A9="BUENAVISTA",$O$4,IF(A9="CANALETE",$O$5,IF(A9="CERETE",$O$6,IF(A9="CHIMA",$O$7,IF(A9="CHINU",$O$8,IF(A9="CIENAGA DE ORO",$O$9,IF(A9="COTORRA",$O$10,IF(A9="LA APARTADA",$O$11,IF(A9="LORICA",$O$12,IF(A9="LOS CORDOBAS",$O$13,IF(A9="MOMIL",$O$14,IF(A9="MONTELIBANO",$O$15,IF(A9="MOÑITOS",$O$16,IF(A9="PLANETA RICA",$O$17,IF(A9="PUEBLO NUEVO",$O$18,IF(A9="PUERTO ESCONDIDO",$O$19,IF(A9="PUERTO LIBERTADOR",$O$20,IF(A9="PURISIMA",$O$21,IF(A9="SAHAGUN",$O$22,IF(A9="SAN ANDRES SOTAVENTO",$O$23,IF(A9="SAN ANTERO",$O$24,IF(A9="SAN BERNARDO DEL VIENTO",$O$25,IF(A9="SAN CARLOS",$O$26,IF(A9="SAN JOSE DE URE",$O$27,IF(A9="SAN PELAYO",$O$28,IF(A9="TIERRALTA",$O$29,IF(A9="TUCHIN",$O$30,IF(A9="VALENCIA",$O$31))))))))))))))))))))))))))))))) -> FALSE | D9: =(IF(A9="MONTERIA",$P$2,IF(A9="AYAPEL",$P$3,IF(A9="BUENAVISTA",$P$4,IF(A9="CANALETE",$P$5,IF(A9="CERETE",$P$6,IF(A9="CHIMA",$P$7,IF(A9="CHINU",$P$8,IF(A9="CIENAGA DE ORO",$P$9,IF(A9="COTORRA",$P$10,IF(A9="LA APARTADA",$P$11,IF(A9="LORICA",$P$12,IF(A9="LOS CORDOBAS",$P$13,IF(A9="MOMIL",$P$14,IF(A9="MONTELIBANO",$P$15,IF(A9="MOÑITOS",$P$16,IF(A9="PLANETA RICA",$P$17,IF(A9="PUEBLO NUEVO",$P$18,IF(A9="PUERTO ESCONDIDO",$P$19,IF(A9="PUERTO LIBERTADOR",$P$20,IF(A9="PURISIMA",$P$21,IF(A9="SAHAGUN",$P$22,IF(A9="SAN ANDRES SOTAVENTO",$P$23,IF(A9="SAN ANTERO",$P$24,IF(A9="SAN BERNARDO DEL VIENTO",$P$25,IF(A9="SAN CARLOS",$P$26,IF(A9="SAN JOSE DE URE",$P$27,IF(A9="SAN PELAYO",$P$28,IF(A9="TIERRALTA",$P$29,IF(A9="TUCHIN",$P$30,IF(A9="VALENCIA",$P$31))))))))))))))))))))))))))))))) -> FALSE | E9: =(IF(A9="MONTERIA",$Q$2,IF(A9="AYAPEL",$Q$3,IF(A9="BUENAVISTA",$Q$4,IF(A9="CANALETE",$Q$5,IF(A9="CERETE",$Q$6,IF(A9="CHIMA",$Q$7,IF(A9="CHINU",$Q$8,IF(A9="CIENAGA DE ORO",$Q$9,IF(A9="COTORRA",$Q$10,IF(A9="LA APARTADA",$Q$11,IF(A9="LORICA",$Q$12,IF(A9="LOS CORDOBAS",$Q$13,IF(A9="MOMIL",$Q$14,IF(A9="MONTELIBANO",$Q$15,IF(A9="MOÑITOS",$Q$16,IF(A9="PLANETA RICA",$Q$17,IF(A9="PUEBLO NUEVO",$Q$18,IF(A9="PUERTO ESCONDIDO",$Q$19,IF(A9="PUERTO LIBERTADOR",$Q$20,IF(A9="PURISIMA",$Q$21,IF(A9="SAHAGUN",$Q$22,IF(A9="SAN ANDRES SOTAVENTO",$Q$23,IF(A9="SAN ANTERO",$Q$24,IF(A9="SAN BERNARDO DEL VIENTO",$Q$25,IF(A9="SAN CARLOS",$Q$26,IF(A9="SAN JOSE DE URE",$Q$27,IF(A9="SAN PELAYO",$Q$28,IF(A9="TIERRALTA",$Q$29,IF(A9="TUCHIN",$Q$30,IF(A9="VALENCIA",$Q$31))))))))))))))))))))))))))))))) -> FALSE | F9: =IFERROR(B9/C9*$H$34,"0") -> 0 | G9: =IFERROR(B9/D9*$H$34,"0") -> 0 | H9: =IFERROR(B9/E9*$H$34,"0") -> 0 | N9: CIENAGA DE ORO | O9: =IF($J$2=2022,POBLACIÓN!F13,POBLACIÓN!G13) -> 61426 | P9: =IF($J$2=2022,POBLACIÓN!I13,POBLACIÓN!J13) -> 22310 | Q9: =IF($J$2=2022,POBLACIÓN!L13,POBLACIÓN!M13) -> 39116
C10: =(IF(A10="MONTERIA",$O$2,IF(A10="AYAPEL",$O$3,IF(A10="BUENAVISTA",$O$4,IF(A10="CANALETE",$O$5,IF(A10="CERETE",$O$6,IF(A10="CHIMA",$O$7,IF(A10="CHINU",$O$8,IF(A10="CIENAGA DE ORO",$O$9,IF(A10="COTORRA",$O$10,IF(A10="LA APARTADA",$O$11,IF(A10="LORICA",$O$12,IF(A10="LOS CORDOBAS",$O$13,IF(A10="MOMIL",$O$14,IF(A10="MONTELIBANO",$O$15,IF(A10="MOÑITOS",$O$16,IF(A10="PLANETA RICA",$O$17,IF(A10="PUEBLO NUEVO",$O$18,IF(A10="PUERTO ESCONDIDO",$O$19,IF(A10="PUERTO LIBERTADOR",$O$20,IF(A10="PURISIMA",$O$21,IF(A10="SAHAGUN",$O$22,IF(A10="SAN ANDRES SOTAVENTO",$O$23,IF(A10="SAN ANTERO",$O$24,IF(A10="SAN BERNARDO DEL VIENTO",$O$25,IF(A10="SAN CARLOS",$O$26,IF(A10="SAN JOSE DE URE",$O$27,IF(A10="SAN PELAYO",$O$28,IF(A10="TIERRALTA",$O$29,IF(A10="TUCHIN",$O$30,IF(A10="VALENCIA",$O$31))))))))))))))))))))))))))))))) -> FALSE | D10: =(IF(A10="MONTERIA",$P$2,IF(A10="AYAPEL",$P$3,IF(A10="BUENAVISTA",$P$4,IF(A10="CANALETE",$P$5,IF(A10="CERETE",$P$6,IF(A10="CHIMA",$P$7,IF(A10="CHINU",$P$8,IF(A10="CIENAGA DE ORO",$P$9,IF(A10="COTORRA",$P$10,IF(A10="LA APARTADA",$P$11,IF(A10="LORICA",$P$12,IF(A10="LOS CORDOBAS",$P$13,IF(A10="MOMIL",$P$14,IF(A10="MONTELIBANO",$P$15,IF(A10="MOÑITOS",$P$16,IF(A10="PLANETA RICA",$P$17,IF(A10="PUEBLO NUEVO",$P$18,IF(A10="PUERTO ESCONDIDO",$P$19,IF(A10="PUERTO LIBERTADOR",$P$20,IF(A10="PURISIMA",$P$21,IF(A10="SAHAGUN",$P$22,IF(A10="SAN ANDRES SOTAVENTO",$P$23,IF(A10="SAN ANTERO",$P$24,IF(A10="SAN BERNARDO DEL VIENTO",$P$25,IF(A10="SAN CARLOS",$P$26,IF(A10="SAN JOSE DE URE",$P$27,IF(A10="SAN PELAYO",$P$28,IF(A10="TIERRALTA",$P$29,IF(A10="TUCHIN",$P$30,IF(A10="VALENCIA",$P$31))))))))))))))))))))))))))))))) -> FALSE | E10: =(IF(A10="MONTERIA",$Q$2,IF(A10="AYAPEL",$Q$3,IF(A10="BUENAVISTA",$Q$4,IF(A10="CANALETE",$Q$5,IF(A10="CERETE",$Q$6,IF(A10="CHIMA",$Q$7,IF(A10="CHINU",$Q$8,IF(A10="CIENAGA DE ORO",$Q$9,IF(A10="COTORRA",$Q$10,IF(A10="LA APARTADA",$Q$11,IF(A10="LORICA",$Q$12,IF(A10="LOS CORDOBAS",$Q$13,IF(A10="MOMIL",$Q$14,IF(A10="MONTELIBANO",$Q$15,IF(A10="MOÑITOS",$Q$16,IF(A10="PLANETA RICA",$Q$17,IF(A10="PUEBLO NUEVO",$Q$18,IF(A10="PUERTO ESCONDIDO",$Q$19,IF(A10="PUERTO LIBERTADOR",$Q$20,IF(A10="PURISIMA",$Q$21,IF(A10="SAHAGUN",$Q$22,IF(A10="SAN ANDRES SOTAVENTO",$Q$23,IF(A10="SAN ANTERO",$Q$24,IF(A10="SAN BERNARDO DEL VIENTO",$Q$25,IF(A10="SAN CARLOS",$Q$26,IF(A10="SAN JOSE DE URE",$Q$27,IF(A10="SAN PELAYO",$Q$28,IF(A10="TIERRALTA",$Q$29,IF(A10="TUCHIN",$Q$30,IF(A10="VALENCIA",$Q$31))))))))))))))))))))))))))))))) -> FALSE | F10: =IFERROR(B10/C10*$H$34,"0") -> 0 | G10: =IFERROR(B10/D10*$H$34,"0") -> 0 | H10: =IFERROR(B10/E10*$H$34,"0") -> 0 | N10: COTORRA | O10: =IF($J$2=2022,POBLACIÓN!F14,POBLACIÓN!G14) -> 19845 | P10: =IF($J$2=2022,POBLACIÓN!I14,POBLACIÓN!J14) -> 6116 | Q10: =IF($J$2=2022,POBLACIÓN!L14,POBLACIÓN!M14) -> 13729
C11: =(IF(A11="MONTERIA",$O$2,IF(A11="AYAPEL",$O$3,IF(A11="BUENAVISTA",$O$4,IF(A11="CANALETE",$O$5,IF(A11="CERETE",$O$6,IF(A11="CHIMA",$O$7,IF(A11="CHINU",$O$8,IF(A11="CIENAGA DE ORO",$O$9,IF(A11="COTORRA",$O$10,IF(A11="LA APARTADA",$O$11,IF(A11="LORICA",$O$12,IF(A11="LOS CORDOBAS",$O$13,IF(A11="MOMIL",$O$14,IF(A11="MONTELIBANO",$O$15,IF(A11="MOÑITOS",$O$16,IF(A11="PLANETA RICA",$O$17,IF(A11="PUEBLO NUEVO",$O$18,IF(A11="PUERTO ESCONDIDO",$O$19,IF(A11="PUERTO LIBERTADOR",$O$20,IF(A11="PURISIMA",$O$21,IF(A11="SAHAGUN",$O$22,IF(A11="SAN ANDRES SOTAVENTO",$O$23,IF(A11="SAN ANTERO",$O$24,IF(A11="SAN BERNARDO DEL VIENTO",$O$25,IF(A11="SAN CARLOS",$O$26,IF(A11="SAN JOSE DE URE",$O$27,IF(A11="SAN PELAYO",$O$28,IF(A11="TIERRALTA",$O$29,IF(A11="TUCHIN",$O$30,IF(A11="VALENCIA",$O$31))))))))))))))))))))))))))))))) -> FALSE | D11: =(IF(A11="MONTERIA",$P$2,IF(A11="AYAPEL",$P$3,IF(A11="BUENAVISTA",$P$4,IF(A11="CANALETE",$P$5,IF(A11="CERETE",$P$6,IF(A11="CHIMA",$P$7,IF(A11="CHINU",$P$8,IF(A11="CIENAGA DE ORO",$P$9,IF(A11="COTORRA",$P$10,IF(A11="LA APARTADA",$P$11,IF(A11="LORICA",$P$12,IF(A11="LOS CORDOBAS",$P$13,IF(A11="MOMIL",$P$14,IF(A11="MONTELIBANO",$P$15,IF(A11="MOÑITOS",$P$16,IF(A11="PLANETA RICA",$P$17,IF(A11="PUEBLO NUEVO",$P$18,IF(A11="PUERTO ESCONDIDO",$P$19,IF(A11="PUERTO LIBERTADOR",$P$20,IF(A11="PURISIMA",$P$21,IF(A11="SAHAGUN",$P$22,IF(A11="SAN ANDRES SOTAVENTO",$P$23,IF(A11="SAN ANTERO",$P$24,IF(A11="SAN BERNARDO DEL VIENTO",$P$25,IF(A11="SAN CARLOS",$P$26,IF(A11="SAN JOSE DE URE",$P$27,IF(A11="SAN PELAYO",$P$28,IF(A11="TIERRALTA",$P$29,IF(A11="TUCHIN",$P$30,IF(A11="VALENCIA",$P$31))))))))))))))))))))))))))))))) -> FALSE | E11: =(IF(A11="MONTERIA",$Q$2,IF(A11="AYAPEL",$Q$3,IF(A11="BUENAVISTA",$Q$4,IF(A11="CANALETE",$Q$5,IF(A11="CERETE",$Q$6,IF(A11="CHIMA",$Q$7,IF(A11="CHINU",$Q$8,IF(A11="CIENAGA DE ORO",$Q$9,IF(A11="COTORRA",$Q$10,IF(A11="LA APARTADA",$Q$11,IF(A11="LORICA",$Q$12,IF(A11="LOS CORDOBAS",$Q$13,IF(A11="MOMIL",$Q$14,IF(A11="MONTELIBANO",$Q$15,IF(A11="MOÑITOS",$Q$16,IF(A11="PLANETA RICA",$Q$17,IF(A11="PUEBLO NUEVO",$Q$18,IF(A11="PUERTO ESCONDIDO",$Q$19,IF(A11="PUERTO LIBERTADOR",$Q$20,IF(A11="PURISIMA",$Q$21,IF(A11="SAHAGUN",$Q$22,IF(A11="SAN ANDRES SOTAVENTO",$Q$23,IF(A11="SAN ANTERO",$Q$24,IF(A11="SAN BERNARDO DEL VIENTO",$Q$25,IF(A11="SAN CARLOS",$Q$26,IF(A11="SAN JOSE DE URE",$Q$27,IF(A11="SAN PELAYO",$Q$28,IF(A11="TIERRALTA",$Q$29,IF(A11="TUCHIN",$Q$30,IF(A11="VALENCIA",$Q$31))))))))))))))))))))))))))))))) -> FALSE | F11: =IFERROR(B11/C11*$H$34,"0") -> 0 | G11: =IFERROR(B11/D11*$H$34,"0") -> 0 | H11: =IFERROR(B11/E11*$H$34,"0") -> 0 | N11: LA APARTADA | O11: =IF($J$2=2022,POBLACIÓN!F15,POBLACIÓN!G15) -> 15446 | P11: =IF($J$2=2022,POBLACIÓN!I15,POBLACIÓN!J15) -> 11696 | Q11: =IF($J$2=2022,POBLACIÓN!L15,POBLACIÓN!M15) -> 3750
C12: =(IF(A12="MONTERIA",$O$2,IF(A12="AYAPEL",$O$3,IF(A12="BUENAVISTA",$O$4,IF(A12="CANALETE",$O$5,IF(A12="CERETE",$O$6,IF(A12="CHIMA",$O$7,IF(A12="CHINU",$O$8,IF(A12="CIENAGA DE ORO",$O$9,IF(A12="COTORRA",$O$10,IF(A12="LA APARTADA",$O$11,IF(A12="LORICA",$O$12,IF(A12="LOS CORDOBAS",$O$13,IF(A12="MOMIL",$O$14,IF(A12="MONTELIBANO",$O$15,IF(A12="MOÑITOS",$O$16,IF(A12="PLANETA RICA",$O$17,IF(A12="PUEBLO NUEVO",$O$18,IF(A12="PUERTO ESCONDIDO",$O$19,IF(A12="PUERTO LIBERTADOR",$O$20,IF(A12="PURISIMA",$O$21,IF(A12="SAHAGUN",$O$22,IF(A12="SAN ANDRES SOTAVENTO",$O$23,IF(A12="SAN ANTERO",$O$24,IF(A12="SAN BERNARDO DEL VIENTO",$O$25,IF(A12="SAN CARLOS",$O$26,IF(A12="SAN JOSE DE URE",$O$27,IF(A12="SAN PELAYO",$O$28,IF(A12="TIERRALTA",$O$29,IF(A12="TUCHIN",$O$30,IF(A12="VALENCIA",$O$31))))))))))))))))))))))))))))))) -> FALSE | D12: =(IF(A12="MONTERIA",$P$2,IF(A12="AYAPEL",$P$3,IF(A12="BUENAVISTA",$P$4,IF(A12="CANALETE",$P$5,IF(A12="CERETE",$P$6,IF(A12="CHIMA",$P$7,IF(A12="CHINU",$P$8,IF(A12="CIENAGA DE ORO",$P$9,IF(A12="COTORRA",$P$10,IF(A12="LA APARTADA",$P$11,IF(A12="LORICA",$P$12,IF(A12="LOS CORDOBAS",$P$13,IF(A12="MOMIL",$P$14,IF(A12="MONTELIBANO",$P$15,IF(A12="MOÑITOS",$P$16,IF(A12="PLANETA RICA",$P$17,IF(A12="PUEBLO NUEVO",$P$18,IF(A12="PUERTO ESCONDIDO",$P$19,IF(A12="PUERTO LIBERTADOR",$P$20,IF(A12="PURISIMA",$P$21,IF(A12="SAHAGUN",$P$22,IF(A12="SAN ANDRES SOTAVENTO",$P$23,IF(A12="SAN ANTERO",$P$24,IF(A12="SAN BERNARDO DEL VIENTO",$P$25,IF(A12="SAN CARLOS",$P$26,IF(A12="SAN JOSE DE URE",$P$27,IF(A12="SAN PELAYO",$P$28,IF(A12="TIERRALTA",$P$29,IF(A12="TUCHIN",$P$30,IF(A12="VALENCIA",$P$31))))))))))))))))))))))))))))))) -> FALSE | E12: =(IF(A12="MONTERIA",$Q$2,IF(A12="AYAPEL",$Q$3,IF(A12="BUENAVISTA",$Q$4,IF(A12="CANALETE",$Q$5,IF(A12="CERETE",$Q$6,IF(A12="CHIMA",$Q$7,IF(A12="CHINU",$Q$8,IF(A12="CIENAGA DE ORO",$Q$9,IF(A12="COTORRA",$Q$10,IF(A12="LA APARTADA",$Q$11,IF(A12="LORICA",$Q$12,IF(A12="LOS CORDOBAS",$Q$13,IF(A12="MOMIL",$Q$14,IF(A12="MONTELIBANO",$Q$15,IF(A12="MOÑITOS",$Q$16,IF(A12="PLANETA RICA",$Q$17,IF(A12="PUEBLO NUEVO",$Q$18,IF(A12="PUERTO ESCONDIDO",$Q$19,IF(A12="PUERTO LIBERTADOR",$Q$20,IF(A12="PURISIMA",$Q$21,IF(A12="SAHAGUN",$Q$22,IF(A12="SAN ANDRES SOTAVENTO",$Q$23,IF(A12="SAN ANTERO",$Q$24,IF(A12="SAN BERNARDO DEL VIENTO",$Q$25,IF(A12="SAN CARLOS",$Q$26,IF(A12="SAN JOSE DE URE",$Q$27,IF(A12="SAN PELAYO",$Q$28,IF(A12="TIERRALTA",$Q$29,IF(A12="TUCHIN",$Q$30,IF(A12="VALENCIA",$Q$31))))))))))))))))))))))))))))))) -> FALSE | F12: =IFERROR(B12/C12*$H$34,"0") -> 0 | G12: =IFERROR(B12/D12*$H$34,"0") -> 0 | H12: =IFERROR(B12/E12*$H$34,"0") -> 0 | N12: LORICA | O12: =IF($J$2=2022,POBLACIÓN!F16,POBLACIÓN!G16) -> 117188 | P12: =IF($J$2=2022,POBLACIÓN!I16,POBLACIÓN!J16) -> 54633 | Q12: =IF($J$2=2022,POBLACIÓN!L16,POBLACIÓN!M16) -> 62555
C13: =(IF(A13="MONTERIA",$O$2,IF(A13="AYAPEL",$O$3,IF(A13="BUENAVISTA",$O$4,IF(A13="CANALETE",$O$5,IF(A13="CERETE",$O$6,IF(A13="CHIMA",$O$7,IF(A13="CHINU",$O$8,IF(A13="CIENAGA DE ORO",$O$9,IF(A13="COTORRA",$O$10,IF(A13="LA APARTADA",$O$11,IF(A13="LORICA",$O$12,IF(A13="LOS CORDOBAS",$O$13,IF(A13="MOMIL",$O$14,IF(A13="MONTELIBANO",$O$15,IF(A13="MOÑITOS",$O$16,IF(A13="PLANETA RICA",$O$17,IF(A13="PUEBLO NUEVO",$O$18,IF(A13="PUERTO ESCONDIDO",$O$19,IF(A13="PUERTO LIBERTADOR",$O$20,IF(A13="PURISIMA",$O$21,IF(A13="SAHAGUN",$O$22,IF(A13="SAN ANDRES SOTAVENTO",$O$23,IF(A13="SAN ANTERO",$O$24,IF(A13="SAN BERNARDO DEL VIENTO",$O$25,IF(A13="SAN CARLOS",$O$26,IF(A13="SAN JOSE DE URE",$O$27,IF(A13="SAN PELAYO",$O$28,IF(A13="TIERRALTA",$O$29,IF(A13="TUCHIN",$O$30,IF(A13="VALENCIA",$O$31))))))))))))))))))))))))))))))) -> FALSE | D13: =(IF(A13="MONTERIA",$P$2,IF(A13="AYAPEL",$P$3,IF(A13="BUENAVISTA",$P$4,IF(A13="CANALETE",$P$5,IF(A13="CERETE",$P$6,IF(A13="CHIMA",$P$7,IF(A13="CHINU",$P$8,IF(A13="CIENAGA DE ORO",$P$9,IF(A13="COTORRA",$P$10,IF(A13="LA APARTADA",$P$11,IF(A13="LORICA",$P$12,IF(A13="LOS CORDOBAS",$P$13,IF(A13="MOMIL",$P$14,IF(A13="MONTELIBANO",$P$15,IF(A13="MOÑITOS",$P$16,IF(A13="PLANETA RICA",$P$17,IF(A13="PUEBLO NUEVO",$P$18,IF(A13="PUERTO ESCONDIDO",$P$19,IF(A13="PUERTO LIBERTADOR",$P$20,IF(A13="PURISIMA",$P$21,IF(A13="SAHAGUN",$P$22,IF(A13="SAN ANDRES SOTAVENTO",$P$23,IF(A13="SAN ANTERO",$P$24,IF(A13="SAN BERNARDO DEL VIENTO",$P$25,IF(A13="SAN CARLOS",$P$26,IF(A13="SAN JOSE DE URE",$P$27,IF(A13="SAN PELAYO",$P$28,IF(A13="TIERRALTA",$P$29,IF(A13="TUCHIN",$P$30,IF(A13="VALENCIA",$P$31))))))))))))))))))))))))))))))) -> FALSE | E13: =(IF(A13="MONTERIA",$Q$2,IF(A13="AYAPEL",$Q$3,IF(A13="BUENAVISTA",$Q$4,IF(A13="CANALETE",$Q$5,IF(A13="CERETE",$Q$6,IF(A13="CHIMA",$Q$7,IF(A13="CHINU",$Q$8,IF(A13="CIENAGA DE ORO",$Q$9,IF(A13="COTORRA",$Q$10,IF(A13="LA APARTADA",$Q$11,IF(A13="LORICA",$Q$12,IF(A13="LOS CORDOBAS",$Q$13,IF(A13="MOMIL",$Q$14,IF(A13="MONTELIBANO",$Q$15,IF(A13="MOÑITOS",$Q$16,IF(A13="PLANETA RICA",$Q$17,IF(A13="PUEBLO NUEVO",$Q$18,IF(A13="PUERTO ESCONDIDO",$Q$19,IF(A13="PUERTO LIBERTADOR",$Q$20,IF(A13="PURISIMA",$Q$21,IF(A13="SAHAGUN",$Q$22,IF(A13="SAN ANDRES SOTAVENTO",$Q$23,IF(A13="SAN ANTERO",$Q$24,IF(A13="SAN BERNARDO DEL VIENTO",$Q$25,IF(A13="SAN CARLOS",$Q$26,IF(A13="SAN JOSE DE URE",$Q$27,IF(A13="SAN PELAYO",$Q$28,IF(A13="TIERRALTA",$Q$29,IF(A13="TUCHIN",$Q$30,IF(A13="VALENCIA",$Q$31))))))))))))))))))))))))))))))) -> FALSE | F13: =IFERROR(B13/C13*$H$34,"0") -> 0 | G13: =IFERROR(B13/D13*$H$34,"0") -> 0 | H13: =IFERROR(B13/E13*$H$34,"0") -> 0 | N13: LOS CORDOBAS | O13: =IF($J$2=2022,POBLACIÓN!F17,POBLACIÓN!G17) -> 19607 | P13: =IF($J$2=2022,POBLACIÓN!I17,POBLACIÓN!J17) -> 3776 | Q13: =IF($J$2=2022,POBLACIÓN!L17,POBLACIÓN!M17) -> 15831
C14: =(IF(A14="MONTERIA",$O$2,IF(A14="AYAPEL",$O$3,IF(A14="BUENAVISTA",$O$4,IF(A14="CANALETE",$O$5,IF(A14="CERETE",$O$6,IF(A14="CHIMA",$O$7,IF(A14="CHINU",$O$8,IF(A14="CIENAGA DE ORO",$O$9,IF(A14="COTORRA",$O$10,IF(A14="LA APARTADA",$O$11,IF(A14="LORICA",$O$12,IF(A14="LOS CORDOBAS",$O$13,IF(A14="MOMIL",$O$14,IF(A14="MONTELIBANO",$O$15,IF(A14="MOÑITOS",$O$16,IF(A14="PLANETA RICA",$O$17,IF(A14="PUEBLO NUEVO",$O$18,IF(A14="PUERTO ESCONDIDO",$O$19,IF(A14="PUERTO LIBERTADOR",$O$20,IF(A14="PURISIMA",$O$21,IF(A14="SAHAGUN",$O$22,IF(A14="SAN ANDRES SOTAVENTO",$O$23,IF(A14="SAN ANTERO",$O$24,IF(A14="SAN BERNARDO DEL VIENTO",$O$25,IF(A14="SAN CARLOS",$O$26,IF(A14="SAN JOSE DE URE",$O$27,IF(A14="SAN PELAYO",$O$28,IF(A14="TIERRALTA",$O$29,IF(A14="TUCHIN",$O$30,IF(A14="VALENCIA",$O$31))))))))))))))))))))))))))))))) -> FALSE | D14: =(IF(A14="MONTERIA",$P$2,IF(A14="AYAPEL",$P$3,IF(A14="BUENAVISTA",$P$4,IF(A14="CANALETE",$P$5,IF(A14="CERETE",$P$6,IF(A14="CHIMA",$P$7,IF(A14="CHINU",$P$8,IF(A14="CIENAGA DE ORO",$P$9,IF(A14="COTORRA",$P$10,IF(A14="LA APARTADA",$P$11,IF(A14="LORICA",$P$12,IF(A14="LOS CORDOBAS",$P$13,IF(A14="MOMIL",$P$14,IF(A14="MONTELIBANO",$P$15,IF(A14="MOÑITOS",$P$16,IF(A14="PLANETA RICA",$P$17,IF(A14="PUEBLO NUEVO",$P$18,IF(A14="PUERTO ESCONDIDO",$P$19,IF(A14="PUERTO LIBERTADOR",$P$20,IF(A14="PURISIMA",$P$21,IF(A14="SAHAGUN",$P$22,IF(A14="SAN ANDRES SOTAVENTO",$P$23,IF(A14="SAN ANTERO",$P$24,IF(A14="SAN BERNARDO DEL VIENTO",$P$25,IF(A14="SAN CARLOS",$P$26,IF(A14="SAN JOSE DE URE",$P$27,IF(A14="SAN PELAYO",$P$28,IF(A14="TIERRALTA",$P$29,IF(A14="TUCHIN",$P$30,IF(A14="VALENCIA",$P$31))))))))))))))))))))))))))))))) -> FALSE | E14: =(IF(A14="MONTERIA",$Q$2,IF(A14="AYAPEL",$Q$3,IF(A14="BUENAVISTA",$Q$4,IF(A14="CANALETE",$Q$5,IF(A14="CERETE",$Q$6,IF(A14="CHIMA",$Q$7,IF(A14="CHINU",$Q$8,IF(A14="CIENAGA DE ORO",$Q$9,IF(A14="COTORRA",$Q$10,IF(A14="LA APARTADA",$Q$11,IF(A14="LORICA",$Q$12,IF(A14="LOS CORDOBAS",$Q$13,IF(A14="MOMIL",$Q$14,IF(A14="MONTELIBANO",$Q$15,IF(A14="MOÑITOS",$Q$16,IF(A14="PLANETA RICA",$Q$17,IF(A14="PUEBLO NUEVO",$Q$18,IF(A14="PUERTO ESCONDIDO",$Q$19,IF(A14="PUERTO LIBERTADOR",$Q$20,IF(A14="PURISIMA",$Q$21,IF(A14="SAHAGUN",$Q$22,IF(A14="SAN ANDRES SOTAVENTO",$Q$23,IF(A14="SAN ANTERO",$Q$24,IF(A14="SAN BERNARDO DEL VIENTO",$Q$25,IF(A14="SAN CARLOS",$Q$26,IF(A14="SAN JOSE DE URE",$Q$27,IF(A14="SAN PELAYO",$Q$28,IF(A14="TIERRALTA",$Q$29,IF(A14="TUCHIN",$Q$30,IF(A14="VALENCIA",$Q$31))))))))))))))))))))))))))))))) -> FALSE | F14: =IFERROR(B14/C14*$H$34,"0") -> 0 | G14: =IFERROR(B14/D14*$H$34,"0") -> 0 | H14: =IFERROR(B14/E14*$H$34,"0") -> 0 | N14: MOMIL | O14: =IF($J$2=2022,POBLACIÓN!F18,POBLACIÓN!G18) -> 20422 | P14: =IF($J$2=2022,POBLACIÓN!I18,POBLACIÓN!J18) -> 11937 | Q14: =IF($J$2=2022,POBLACIÓN!L18,POBLACIÓN!M18) -> 8485
C15: =(IF(A15="MONTERIA",$O$2,IF(A15="AYAPEL",$O$3,IF(A15="BUENAVISTA",$O$4,IF(A15="CANALETE",$O$5,IF(A15="CERETE",$O$6,IF(A15="CHIMA",$O$7,IF(A15="CHINU",$O$8,IF(A15="CIENAGA DE ORO",$O$9,IF(A15="COTORRA",$O$10,IF(A15="LA APARTADA",$O$11,IF(A15="LORICA",$O$12,IF(A15="LOS CORDOBAS",$O$13,IF(A15="MOMIL",$O$14,IF(A15="MONTELIBANO",$O$15,IF(A15="MOÑITOS",$O$16,IF(A15="PLANETA RICA",$O$17,IF(A15="PUEBLO NUEVO",$O$18,IF(A15="PUERTO ESCONDIDO",$O$19,IF(A15="PUERTO LIBERTADOR",$O$20,IF(A15="PURISIMA",$O$21,IF(A15="SAHAGUN",$O$22,IF(A15="SAN ANDRES SOTAVENTO",$O$23,IF(A15="SAN ANTERO",$O$24,IF(A15="SAN BERNARDO DEL VIENTO",$O$25,IF(A15="SAN CARLOS",$O$26,IF(A15="SAN JOSE DE URE",$O$27,IF(A15="SAN PELAYO",$O$28,IF(A15="TIERRALTA",$O$29,IF(A15="TUCHIN",$O$30,IF(A15="VALENCIA",$O$31))))))))))))))))))))))))))))))) -> FALSE | D15: =(IF(A15="MONTERIA",$P$2,IF(A15="AYAPEL",$P$3,IF(A15="BUENAVISTA",$P$4,IF(A15="CANALETE",$P$5,IF(A15="CERETE",$P$6,IF(A15="CHIMA",$P$7,IF(A15="CHINU",$P$8,IF(A15="CIENAGA DE ORO",$P$9,IF(A15="COTORRA",$P$10,IF(A15="LA APARTADA",$P$11,IF(A15="LORICA",$P$12,IF(A15="LOS CORDOBAS",$P$13,IF(A15="MOMIL",$P$14,IF(A15="MONTELIBANO",$P$15,IF(A15="MOÑITOS",$P$16,IF(A15="PLANETA RICA",$P$17,IF(A15="PUEBLO NUEVO",$P$18,IF(A15="PUERTO ESCONDIDO",$P$19,IF(A15="PUERTO LIBERTADOR",$P$20,IF(A15="PURISIMA",$P$21,IF(A15="SAHAGUN",$P$22,IF(A15="SAN ANDRES SOTAVENTO",$P$23,IF(A15="SAN ANTERO",$P$24,IF(A15="SAN BERNARDO DEL VIENTO",$P$25,IF(A15="SAN CARLOS",$P$26,IF(A15="SAN JOSE DE URE",$P$27,IF(A15="SAN PELAYO",$P$28,IF(A15="TIERRALTA",$P$29,IF(A15="TUCHIN",$P$30,IF(A15="VALENCIA",$P$31))))))))))))))))))))))))))))))) -> FALSE | E15: =(IF(A15="MONTERIA",$Q$2,IF(A15="AYAPEL",$Q$3,IF(A15="BUENAVISTA",$Q$4,IF(A15="CANALETE",$Q$5,IF(A15="CERETE",$Q$6,IF(A15="CHIMA",$Q$7,IF(A15="CHINU",$Q$8,IF(A15="CIENAGA DE ORO",$Q$9,IF(A15="COTORRA",$Q$10,IF(A15="LA APARTADA",$Q$11,IF(A15="LORICA",$Q$12,IF(A15="LOS CORDOBAS",$Q$13,IF(A15="MOMIL",$Q$14,IF(A15="MONTELIBANO",$Q$15,IF(A15="MOÑITOS",$Q$16,IF(A15="PLANETA RICA",$Q$17,IF(A15="PUEBLO NUEVO",$Q$18,IF(A15="PUERTO ESCONDIDO",$Q$19,IF(A15="PUERTO LIBERTADOR",$Q$20,IF(A15="PURISIMA",$Q$21,IF(A15="SAHAGUN",$Q$22,IF(A15="SAN ANDRES SOTAVENTO",$Q$23,IF(A15="SAN ANTERO",$Q$24,IF(A15="SAN BERNARDO DEL VIENTO",$Q$25,IF(A15="SAN CARLOS",$Q$26,IF(A15="SAN JOSE DE URE",$Q$27,IF(A15="SAN PELAYO",$Q$28,IF(A15="TIERRALTA",$Q$29,IF(A15="TUCHIN",$Q$30,IF(A15="VALENCIA",$Q$31))))))))))))))))))))))))))))))) -> FALSE | F15: =IFERROR(B15/C15*$H$34,"0") -> 0 | G15: =IFERROR(B15/D15*$H$34,"0") -> 0 | H15: =IFERROR(B15/E15*$H$34,"0") -> 0 | N15: MONTELIBANO | O15: =IF($J$2=2022,POBLACIÓN!F19,POBLACIÓN!G19) -> 87187 | P15: =IF($J$2=2022,POBLACIÓN!I19,POBLACIÓN!J19) -> 64432 | Q15: =IF($J$2=2022,POBLACIÓN!L19,POBLACIÓN!M19) -> 22755
